Workbook

Sheet Tracker
A1: MedVoice v3.4 — 6-Week Delivery Tracker
A2: Andalusia Group | AI Team | Update only the yellow cells. Task rows, flags, team progress and the Gantt update automatically.
A5: Project start | C5: 46299 | H5: Team | I5: Hours | J5: Planned % | K5: Done % | L5: Blocked | M5: Late | N5: To check
A6: Meeting date | C6: 46299 | H6: Ahmed Hamdy | I6: =SUMPRODUCT(($AA$14:$AA$400="Ahmed Hamdy")*($Z$14:$Z$400="S")*$D$14:$D$400) -> 86 | J6: =IFERROR(SUMPRODUCT(($AA$14:$AA$400="Ahmed Hamdy")*($Z$14:$Z$400="T")*$Y$14:$Y$400*IF($C$7<$W$14:$W$400,0,IF($C$7>=$X$14:$X$400,1,($C$7-$W$14:$W$400+1)/$Y$14:$Y$400)))/SUMPRODUCT(($AA$14:$AA$400="Ahmed Hamdy")*($Z$14:$Z$400="T")*$Y$14:$Y$400),0) -> 0 | K6: =IFERROR(SUMPRODUCT(($AA$14:$AA$400="Ahmed Hamdy")*($Z$14:$Z$400="T")*$Y$14:$Y$400*$K$14:$K$400)/SUMPRODUCT(($AA$14:$AA$400="Ahmed Hamdy")*($Z$14:$Z$400="T")*$Y$14:$Y$400),0) -> 0.13259259 | L6: =SUMPRODUCT(($AA$14:$AA$400="Ahmed Hamdy")*($Z$14:$Z$400="T")*($J$14:$J$400="Blocked")) -> 0 | M6: =SUMPRODUCT(($AA$14:$AA$400="Ahmed Hamdy")*($Z$14:$Z$400="T")*($M$14:$M$400="Late")) -> 0 | N6: =SUMPRODUCT(($AA$14:$AA$400="Ahmed Hamdy")*($M$14:$M$400="Check")) -> 7
A7: Working day | C7: =MAX(0,INT((C6-C5)/7)*5+MIN(MOD(C6-C5,7),4)+1) -> 1 | H7: Doha | I7: =SUMPRODUCT(($AA$14:$AA$400="Doha")*($Z$14:$Z$400="S")*$D$14:$D$400) -> 89 | J7: =IFERROR(SUMPRODUCT(($AA$14:$AA$400="Doha")*($Z$14:$Z$400="T")*$Y$14:$Y$400*IF($C$7<$W$14:$W$400,0,IF($C$7>=$X$14:$X$400,1,($C$7-$W$14:$W$400+1)/$Y$14:$Y$400)))/SUMPRODUCT(($AA$14:$AA$400="Doha")*($Z$14:$Z$400="T")*$Y$14:$Y$400),0) -> 0 | K7: =IFERROR(SUMPRODUCT(($AA$14:$AA$400="Doha")*($Z$14:$Z$400="T")*$Y$14:$Y$400*$K$14:$K$400)/SUMPRODUCT(($AA$14:$AA$400="Doha")*($Z$14:$Z$400="T")*$Y$14:$Y$400),0) -> 0.23396825 | L7: =SUMPRODUCT(($AA$14:$AA$400="Doha")*($Z$14:$Z$400="T")*($J$14:$J$400="Blocked")) -> 0 | M7: =SUMPRODUCT(($AA$14:$AA$400="Doha")*($Z$14:$Z$400="T")*($M$14:$M$400="Late")) -> 0 | N7: =SUMPRODUCT(($AA$14:$AA$400="Doha")*($M$14:$M$400="Check")) -> 0
A8: Baseline go-live | C8: 46338 | H8: Mohamed Essam | I8: =SUMPRODUCT(($AA$14:$AA$400="Mohamed Essam")*($Z$14:$Z$400="S")*$D$14:$D$400) -> 102 | J8: =IFERROR(SUMPRODUCT(($AA$14:$AA$400="Mohamed Essam")*($Z$14:$Z$400="T")*$Y$14:$Y$400*IF($C$7<$W$14:$W$400,0,IF($C$7>=$X$14:$X$400,1,($C$7-$W$14:$W$400+1)/$Y$14:$Y$400)))/SUMPRODUCT(($AA$14:$AA$400="Mohamed Essam")*($Z$14:$Z$400="T")*$Y$14:$Y$400),0) -> 0 | K8: =IFERROR(SUMPRODUCT(($AA$14:$AA$400="Mohamed Essam")*($Z$14:$Z$400="T")*$Y$14:$Y$400*$K$14:$K$400)/SUMPRODUCT(($AA$14:$AA$400="Mohamed Essam")*($Z$14:$Z$400="T")*$Y$14:$Y$400),0) -> 0 | L8: =SUMPRODUCT(($AA$14:$AA$400="Mohamed Essam")*($Z$14:$Z$400="T")*($J$14:$J$400="Blocked")) -> 0 | M8: =SUMPRODUCT(($AA$14:$AA$400="Mohamed Essam")*($Z$14:$Z$400="T")*($M$14:$M$400="Late")) -> 0 | N8: =SUMPRODUCT(($AA$14:$AA$400="Mohamed Essam")*($M$14:$M$400="Check")) -> 5
A9: Forecast go-live | C9: =$C$5+INT((INDEX($X:$X,MATCH("P2",$A:$A,0))-1)/5)*7+MOD(INDEX($X:$X,MATCH("P2",$A:$A,0))-1,5) -> 46334 | H9: External teams | I9: — | J9: =IFERROR(SUMPRODUCT(($AA$14:$AA$400="Ext")*($Z$14:$Z$400="T")*$Y$14:$Y$400*IF($C$7<$W$14:$W$400,0,IF($C$7>=$X$14:$X$400,1,($C$7-$W$14:$W$400+1)/$Y$14:$Y$400)))/SUMPRODUCT(($AA$14:$AA$400="Ext")*($Z$14:$Z$400="T")*$Y$14:$Y$400),0) -> 0 | K9: =IFERROR(SUMPRODUCT(($AA$14:$AA$400="Ext")*($Z$14:$Z$400="T")*$Y$14:$Y$400*$K$14:$K$400)/SUMPRODUCT(($AA$14:$AA$400="Ext")*($Z$14:$Z$400="T")*$Y$14:$Y$400),0) -> 0.1547619 | L9: =SUMPRODUCT(($AA$14:$AA$400="Ext")*($Z$14:$Z$400="T")*($J$14:$J$400="Blocked")) -> 0 | M9: =SUMPRODUCT(($AA$14:$AA$400="Ext")*($Z$14:$Z$400="T")*($M$14:$M$400="Late")) -> 0 | N9: =SUMPRODUCT(($AA$14:$AA$400="Ext")*($M$14:$M$400="Check")) -> 1
A10: Ahead (+) / behind (−) | C10: =NETWORKDAYS.INTL(C9,C8,7)-1 -> 4 | H10: Whole project | I10: =SUMPRODUCT(($Z$14:$Z$400="S")*$D$14:$D$400) -> 277 | J10: =IFERROR(SUMPRODUCT(($Z$14:$Z$400="T")*$Y$14:$Y$400*IF($C$7<$W$14:$W$400,0,IF($C$7>=$X$14:$X$400,1,($C$7-$W$14:$W$400+1)/$Y$14:$Y$400)))/SUMPRODUCT(($Z$14:$Z$400="T")*$Y$14:$Y$400),0) -> 0 | K10: =IFERROR(SUMPRODUCT(($Z$14:$Z$400="T")*$Y$14:$Y$400*$K$14:$K$400)/SUMPRODUCT(($Z$14:$Z$400="T")*$Y$14:$Y$400),0) -> 0.1363456 | L10: =SUMPRODUCT(($Z$14:$Z$400="T")*($J$14:$J$400="Blocked")) -> 0 | M10: =SUMPRODUCT(($Z$14:$Z$400="T")*($M$14:$M$400="Late")) -> 0 | N10: =SUMPRODUCT(($M$14:$M$400="Check")) -> 0
H11: Planned % = where the plan expects us on the meeting date. "To check" = status and % do not match (e.g. In progress at 0%).
P12: =$C$5+0 -> 46299 | Q12: =$C$5+7 -> 46306 | R12: =$C$5+14 -> 46313 | S12: =$C$5+21 -> 46320 | T12: =$C$5+28 -> 46327 | U12: =$C$5+35 -> 46334
A13: ID | B13: Task / subtask | C13: Owner | D13: Hours | E13: Days | F13: Start | G13: End | H13: Depends on | I13: Done when | J13: Status | K13: % done | L13: Checklist | M13: Flag | N13: Notes / blockers | P13: W1 | Q13: W2 | R13: W3 | S13: W4 | T13: W5 | U13: W6 | W13: SD | X13: ED | Y13: DAYS | Z13: LVL | AA13: TEAM | AB13: PREV | AC13: P0
A14: PRE-REQUISITES — outside the AI team
A15: X1 | B15: Approve use of de-identified logged sessions as the gold set | C15: Compliance | D15: 1 | E15: 5 | F15: =$C$5+INT((W15-1)/5)*7+MOD(W15-1,5) -> 46299 | G15: =$C$5+INT((X15-1)/5)*7+MOD(X15-1,5) -> 46303 | H15: — | I15: Signed approval received | J15: In progress | K15: 0.5 | L15: =IFERROR(COUNTIFS(Checklist!$D:$D,"X1",Checklist!$I:$I,"Yes")/COUNTIF(Checklist!$D:$D,"X1"),0) -> 0 | M15: =IF(AND(J15="Done",K15<1),"Check",IF(AND(J15="In progress",K15=0),"Check",IF(AND(K15>=1,J15<>"Done"),"Check",IF(J15="Done","Done",IF(J15="Blocked","Blocked",IF(AND($C$7>X15,K15<1),"Late","")))))) | N15: Essam calls Germeen | P15: =IF(AND(W15<=5,X15>=1),1,"") -> 1 | Q15: =IF(AND(W15<=10,X15>=6),1,"") | R15: =IF(AND(W15<=15,X15>=11),1,"") | S15: =IF(AND(W15<=20,X15>=16),1,"") | T15: =IF(AND(W15<=25,X15>=21),1,"") | U15: =IF(AND(W15<=30,X15>=26),1,"") | W15: =MAX(IFERROR(INDEX($X$14:$X$400,MATCH(AC15,$A$14:$A$400,0)),0),IFERROR(INDEX($X$14:$X$400,MATCH(AD15,$A$14:$A$400,0)),0),IFERROR(INDEX($X$14:$X$400,MATCH(AE15,$A$14:$A$400,0)),0),IFERROR(INDEX($X$14:$X$400,MATCH(AF15,$A$14:$A$400,0)),0),IFERROR(INDEX($X$14:$X$400,MATCH(AG15,$A$14:$A$400,0)),0),IFERROR(INDEX($X$14:$X$400,MATCH(AH15,$A$14:$A$400,0)),0),IFERROR(INDEX($X$14:$X$400,MATCH(AI15,$A$14:$A$400,0)),0),IFERROR(INDEX($X$14:$X$400,MATCH(AB15,$A$14:$A$400,0)),0))+1 -> 1 | X15: =W15+Y15-1 -> 5 | Y15: =E15 -> 5 | Z15: T | AA15: Ext
A16: X2 | B16: Export ICD-10 code master from the HIS coding system | C16: Coding team | D16: 1 | E16: 3 | F16: =$C$5+INT((W16-1)/5)*7+MOD(W16-1,5) -> 46299 | G16: =$C$5+INT((X16-1)/5)*7+MOD(X16-1,5) -> 46301 | H16: — | I16: File delivered and readable | J16: In progress | K16: 0.5 | L16: =IFERROR(COUNTIFS(Checklist!$D:$D,"X2",Checklist!$I:$I,"Yes")/COUNTIF(Checklist!$D:$D,"X2"),0) -> 0 | M16: =IF(AND(J16="Done",K16<1),"Check",IF(AND(J16="In progress",K16=0),"Check",IF(AND(K16>=1,J16<>"Done"),"Check",IF(J16="Done","Done",IF(J16="Blocked","Blocked",IF(AND($C$7>X16,K16<1),"Late","")))))) | N16: Essam calls Germeen | P16: =IF(AND(W16<=5,X16>=1),1,"") -> 1 | Q16: =IF(AND(W16<=10,X16>=6),1,"") | R16: =IF(AND(W16<=15,X16>=11),1,"") | S16: =IF(AND(W16<=20,X16>=16),1,"") | T16: =IF(AND(W16<=25,X16>=21),1,"") | U16: =IF(AND(W16<=30,X16>=26),1,"") | W16: =MAX(IFERROR(INDEX($X$14:$X$400,MATCH(AC16,$A$14:$A$400,0)),0),IFERROR(INDEX($X$14:$X$400,MATCH(AD16,$A$14:$A$400,0)),0),IFERROR(INDEX($X$14:$X$400,MATCH(AE16,$A$14:$A$400,0)),0),IFERROR(INDEX($X$14:$X$400,MATCH(AF16,$A$14:$A$400,0)),0),IFERROR(INDEX($X$14:$X$400,MATCH(AG16,$A$14:$A$400,0)),0),IFERROR(INDEX($X$14:$X$400,MATCH(AH16,$A$14:$A$400,0)),0),IFERROR(INDEX($X$14:$X$400,MATCH(AI16,$A$14:$A$400,0)),0),IFERROR(INDEX($X$14:$X$400,MATCH(AB16,$A$14:$A$400,0)),0))+1 -> 1 | X16: =W16+Y16-1 -> 3 | Y16: =E16 -> 3 | Z16: T | AA16: Ext
A17: X3 | B17: Confirm residency: Foundry region; continued use of Munsit and Voxtral APIs | C17: Compliance | D17: 1 | E17: 5 | F17: =$C$5+INT((W17-1)/5)*7+MOD(W17-1,5) -> 46299 | G17: =$C$5+INT((X17-1)/5)*7+MOD(X17-1,5) -> 46303 | H17: — | I17: Written approval | J17: In progress | K17: 0.5 | L17: =IFERROR(COUNTIFS(Checklist!$D:$D,"X3",Checklist!$I:$I,"Yes")/COUNTIF(Checklist!$D:$D,"X3"),0) -> 0 | M17: =IF(AND(J17="Done",K17<1),"Check",IF(AND(J17="In progress",K17=0),"Check",IF(AND(K17>=1,J17<>"Done"),"Check",IF(J17="Done","Done",IF(J17="Blocked","Blocked",IF(AND($C$7>X17,K17<1),"Late","")))))) | N17: Essam calls Germeen | P17: =IF(AND(W17<=5,X17>=1),1,"") -> 1 | Q17: =IF(AND(W17<=10,X17>=6),1,"") | R17: =IF(AND(W17<=15,X17>=11),1,"") | S17: =IF(AND(W17<=20,X17>=16),1,"") | T17: =IF(AND(W17<=25,X17>=21),1,"") | U17: =IF(AND(W17<=30,X17>=26),1,"") | W17: =MAX(IFERROR(INDEX($X$14:$X$400,MATCH(AC17,$A$14:$A$400,0)),0),IFERROR(INDEX($X$14:$X$400,MATCH(AD17,$A$14:$A$400,0)),0),IFERROR(INDEX($X$14:$X$400,MATCH(AE17,$A$14:$A$400,0)),0),IFERROR(INDEX($X$14:$X$400,MATCH(AF17,$A$14:$A$400,0)),0),IFERROR(INDEX($X$14:$X$400,MATCH(AG17,$A$14:$A$400,0)),0),IFERROR(INDEX($X$14:$X$400,MATCH(AH17,$A$14:$A$400,0)),0),IFERROR(INDEX($X$14:$X$400,MATCH(AI17,$A$14:$A$400,0)),0),IFERROR(INDEX($X$14:$X$400,MATCH(AB17,$A$14:$A$400,0)),0))+1 -> 1 | X17: =W17+Y17-1 -> 5 | Y17: =E17 -> 5 | Z17: T | AA17: Ext
A18: X4 | B18: Sign acceptance thresholds and pilot site | C18: Steering | D18: 1 | E18: 2 | F18: =$C$5+INT((W18-1)/5)*7+MOD(W18-1,5) -> 46299 | G18: =$C$5+INT((X18-1)/5)*7+MOD(X18-1,5) -> 46300 | H18: — | I18: Signed gate sheet | J18: In progress | K18: 0 | L18: =IFERROR(COUNTIFS(Checklist!$D:$D,"X4",Checklist!$I:$I,"Yes")/COUNTIF(Checklist!$D:$D,"X4"),0) -> 0 | M18: =IF(AND(J18="Done",K18<1),"Check",IF(AND(J18="In progress",K18=0),"Check",IF(AND(K18>=1,J18<>"Done"),"Check",IF(J18="Done","Done",IF(J18="Blocked","Blocked",IF(AND($C$7>X18,K18<1),"Late","")))))) -> Check | N18: Asked Doha to prepare | P18: =IF(AND(W18<=5,X18>=1),1,"") -> 1 | Q18: =IF(AND(W18<=10,X18>=6),1,"") | R18: =IF(AND(W18<=15,X18>=11),1,"") | S18: =IF(AND(W18<=20,X18>=16),1,"") | T18: =IF(AND(W18<=25,X18>=21),1,"") | U18: =IF(AND(W18<=30,X18>=26),1,"") | W18: =MAX(IFERROR(INDEX($X$14:$X$400,MATCH(AC18,$A$14:$A$400,0)),0),IFERROR(INDEX($X$14:$X$400,MATCH(AD18,$A$14:$A$400,0)),0),IFERROR(INDEX($X$14:$X$400,MATCH(AE18,$A$14:$A$400,0)),0),IFERROR(INDEX($X$14:$X$400,MATCH(AF18,$A$14:$A$400,0)),0),IFERROR(INDEX($X$14:$X$400,MATCH(AG18,$A$14:$A$400,0)),0),IFERROR(INDEX($X$14:$X$400,MATCH(AH18,$A$14:$A$400,0)),0),IFERROR(INDEX($X$14:$X$400,MATCH(AI18,$A$14:$A$400,0)),0),IFERROR(INDEX($X$14:$X$400,MATCH(AB18,$A$14:$A$400,0)),0))+1 -> 1 | X18: =W18+Y18-1 -> 2 | Y18: =E18 -> 2 | Z18: T | AA18: Ext
A19: AHMED HAMDY — Platform & performance
A20: A1 | B20: Fix LLM concurrency: shared async client, 45 s timeout, backoff + jitter, per-model limits, async streaming | C20: Ahmed Hamdy | D20: =SUM(D21:D25) -> 9 | E20: =ROUNDUP(D20/8,0) -> 2 | F20: =$C$5+INT((W20-1)/5)*7+MOD(W20-1,5) -> 46299 | G20: =$C$5+INT((X20-1)/5)*7+MOD(X20-1,5) -> 46300 | H20: — | I20: 30 parallel analyses complete; no event-loop blocking; ≤ 3 retries each | J20: =IF(K20>=1,"Done",IF(COUNTIF(J21:J25,"Blocked")>0,"Blocked",IF(OR(K20>0,COUNTIF(J21:J25,"In progress")>0),"In progress","Not started"))) -> In progress | K20: =IFERROR(SUMPRODUCT(D21:D25,K21:K25)/D20,0) -> 0.99444444 | L20: =IFERROR(SUMPRODUCT(D21:D25,L21:L25)/D20,0) -> 0 | M20: =IF(J20="Done","Done",IF(J20="Blocked","Blocked",IF(AND($C$7>X20,K20<1),"Late",""))) | N20: =IF(COUNTIF(J21:J25,"Blocked")>0,"Blocked subtask — see below","") | P20: =IF(AND(W20<=5,X20>=1),1,"") -> 1 | Q20: =IF(AND(W20<=10,X20>=6),1,"") | R20: =IF(AND(W20<=15,X20>=11),1,"") | S20: =IF(AND(W20<=20,X20>=16),1,"") | T20: =IF(AND(W20<=25,X20>=21),1,"") | U20: =IF(AND(W20<=30,X20>=26),1,"") | W20: =MAX(IFERROR(INDEX($X$14:$X$400,MATCH(AC20,$A$14:$A$400,0)),0),IFERROR(INDEX($X$14:$X$400,MATCH(AD20,$A$14:$A$400,0)),0),IFERROR(INDEX($X$14:$X$400,MATCH(AE20,$A$14:$A$400,0)),0),IFERROR(INDEX($X$14:$X$400,MATCH(AF20,$A$14:$A$400,0)),0),IFERROR(INDEX($X$14:$X$400,MATCH(AG20,$A$14:$A$400,0)),0),IFERROR(INDEX($X$14:$X$400,MATCH(AH20,$A$14:$A$400,0)),0),IFERROR(INDEX($X$14:$X$400,MATCH(AI20,$A$14:$A$400,0)),0),IFERROR(INDEX($X$14:$X$400,MATCH(AB20,$A$14:$A$400,0)),0))+1 -> 1 | X20: =W20+Y20-1 -> 2 | Y20: =E20 -> 2 | Z20: T | AA20: Ahmed Hamdy
A21: A1.1 | B21: Shared async client + 45 s timeout, no hidden retries | C21: Ahmed Hamdy | D21: 3 | E21: =X21-W21+1 -> 1 | F21: =$C$5+INT((W21-1)/5)*7+MOD(W21-1,5) -> 46299 | G21: =$C$5+INT((X21-1)/5)*7+MOD(X21-1,5) -> 46299 | J21: Done | K21: 1 | L21: =IFERROR(COUNTIFS(Checklist!$D:$D,"A1.1",Checklist!$I:$I,"Yes")/COUNTIF(Checklist!$D:$D,"A1.1"),0) -> 0 | M21: =IF(AND(J21="Done",K21<1),"Check",IF(AND(J21="In progress",K21=0),"Check",IF(AND(K21>=1,J21<>"Done"),"Check",IF(J21="Done","Done",IF(J21="Blocked","Blocked",IF(AND($C$7>X21,K21<1),"Late","")))))) -> Done | P21: =IF(AND(W21<=5,X21>=1),2,"") -> 2 | Q21: =IF(AND(W21<=10,X21>=6),2,"") | R21: =IF(AND(W21<=15,X21>=11),2,"") | S21: =IF(AND(W21<=20,X21>=16),2,"") | T21: =IF(AND(W21<=25,X21>=21),2,"") | U21: =IF(AND(W21<=30,X21>=26),2,"") | W21: =$W$20+INT(SUM(D$21:D21)/8-D21/8+0.0001) -> 1 | X21: =MAX(W21,$W$20+ROUNDUP(SUM(D$21:D21)/8,0)-1) -> 1 | Y21: =E21 -> 1 | Z21: S | AA21: Ahmed Hamdy
A22: A1.2 | B22: Async streaming for refine / translate | C22: Ahmed Hamdy | D22: 1 | E22: =X22-W22+1 -> 1 | F22: =$C$5+INT((W22-1)/5)*7+MOD(W22-1,5) -> 46299 | G22: =$C$5+INT((X22-1)/5)*7+MOD(X22-1,5) -> 46299 | J22: Done | K22: 1 | L22: =IFERROR(COUNTIFS(Checklist!$D:$D,"A1.2",Checklist!$I:$I,"Yes")/COUNTIF(Checklist!$D:$D,"A1.2"),0) -> 0 | M22: =IF(AND(J22="Done",K22<1),"Check",IF(AND(J22="In progress",K22=0),"Check",IF(AND(K22>=1,J22<>"Done"),"Check",IF(J22="Done","Done",IF(J22="Blocked","Blocked",IF(AND($C$7>X22,K22<1),"Late","")))))) -> Done | P22: =IF(AND(W22<=5,X22>=1),2,"") -> 2 | Q22: =IF(AND(W22<=10,X22>=6),2,"") | R22: =IF(AND(W22<=15,X22>=11),2,"") | S22: =IF(AND(W22<=20,X22>=16),2,"") | T22: =IF(AND(W22<=25,X22>=21),2,"") | U22: =IF(AND(W22<=30,X22>=26),2,"") | W22: =$W$20+INT(SUM(D$21:D22)/8-D22/8+0.0001) -> 1 | X22: =MAX(W22,$W$20+ROUNDUP(SUM(D$21:D22)/8,0)-1) -> 1 | Y22: =E22 -> 1 | Z22: S | AA22: Ahmed Hamdy
A23: A1.3 | B23: Backoff + jitter on 429/5xx; remove key rotation | C23: Ahmed Hamdy | D23: 1 | E23: =X23-W23+1 -> 1 | F23: =$C$5+INT((W23-1)/5)*7+MOD(W23-1,5) -> 46299 | G23: =$C$5+INT((X23-1)/5)*7+MOD(X23-1,5) -> 46299 | J23: In progress | K23: 0.95 | L23: =IFERROR(COUNTIFS(Checklist!$D:$D,"A1.3",Checklist!$I:$I,"Yes")/COUNTIF(Checklist!$D:$D,"A1.3"),0) -> 0 | M23: =IF(AND(J23="Done",K23<1),"Check",IF(AND(J23="In progress",K23=0),"Check",IF(AND(K23>=1,J23<>"Done"),"Check",IF(J23="Done","Done",IF(J23="Blocked","Blocked",IF(AND($C$7>X23,K23<1),"Late","")))))) | P23: =IF(AND(W23<=5,X23>=1),2,"") -> 2 | Q23: =IF(AND(W23<=10,X23>=6),2,"") | R23: =IF(AND(W23<=15,X23>=11),2,"") | S23: =IF(AND(W23<=20,X23>=16),2,"") | T23: =IF(AND(W23<=25,X23>=21),2,"") | U23: =IF(AND(W23<=30,X23>=26),2,"") | W23: =$W$20+INT(SUM(D$21:D23)/8-D23/8+0.0001) -> 1 | X23: =MAX(W23,$W$20+ROUNDUP(SUM(D$21:D23)/8,0)-1) -> 1 | Y23: =E23 -> 1 | Z23: S | AA23: Ahmed Hamdy
A24: A1.4 | B24: Per-model concurrency limits (semaphores) | C24: Ahmed Hamdy | D24: 1 | E24: =X24-W24+1 -> 1 | F24: =$C$5+INT((W24-1)/5)*7+MOD(W24-1,5) -> 46299 | G24: =$C$5+INT((X24-1)/5)*7+MOD(X24-1,5) -> 46299 | J24: Done | K24: 1 | L24: =IFERROR(COUNTIFS(Checklist!$D:$D,"A1.4",Checklist!$I:$I,"Yes")/COUNTIF(Checklist!$D:$D,"A1.4"),0) -> 0 | M24: =IF(AND(J24="Done",K24<1),"Check",IF(AND(J24="In progress",K24=0),"Check",IF(AND(K24>=1,J24<>"Done"),"Check",IF(J24="Done","Done",IF(J24="Blocked","Blocked",IF(AND($C$7>X24,K24<1),"Late","")))))) -> Done | P24: =IF(AND(W24<=5,X24>=1),2,"") -> 2 | Q24: =IF(AND(W24<=10,X24>=6),2,"") | R24: =IF(AND(W24<=15,X24>=11),2,"") | S24: =IF(AND(W24<=20,X24>=16),2,"") | T24: =IF(AND(W24<=25,X24>=21),2,"") | U24: =IF(AND(W24<=30,X24>=26),2,"") | W24: =$W$20+INT(SUM(D$21:D24)/8-D24/8+0.0001) -> 1 | X24: =MAX(W24,$W$20+ROUNDUP(SUM(D$21:D24)/8,0)-1) -> 1 | Y24: =E24 -> 1 | Z24: S | AA24: Ahmed Hamdy
A25: A1.5 | B25: Test: 30 parallel analyses | C25: Ahmed Hamdy | D25: 3 | E25: =X25-W25+1 -> 2 | F25: =$C$5+INT((W25-1)/5)*7+MOD(W25-1,5) -> 46299 | G25: =$C$5+INT((X25-1)/5)*7+MOD(X25-1,5) -> 46300 | J25: Done | K25: 1 | L25: =IFERROR(COUNTIFS(Checklist!$D:$D,"A1.5",Checklist!$I:$I,"Yes")/COUNTIF(Checklist!$D:$D,"A1.5"),0) -> 0 | M25: =IF(AND(J25="Done",K25<1),"Check",IF(AND(J25="In progress",K25=0),"Check",IF(AND(K25>=1,J25<>"Done"),"Check",IF(J25="Done","Done",IF(J25="Blocked","Blocked",IF(AND($C$7>X25,K25<1),"Late","")))))) -> Done | P25: =IF(AND(W25<=5,X25>=1),2,"") -> 2 | Q25: =IF(AND(W25<=10,X25>=6),2,"") | R25: =IF(AND(W25<=15,X25>=11),2,"") | S25: =IF(AND(W25<=20,X25>=16),2,"") | T25: =IF(AND(W25<=25,X25>=21),2,"") | U25: =IF(AND(W25<=30,X25>=26),2,"") | W25: =$W$20+INT(SUM(D$21:D25)/8-D25/8+0.0001) -> 1 | X25: =MAX(W25,$W$20+ROUNDUP(SUM(D$21:D25)/8,0)-1) -> 2 | Y25: =E25 -> 2 | Z25: S | AA25: Ahmed Hamdy
A26: A2 | B26: Azure foundation: Key Vault, managed identities, private endpoints, App Insights | C26: Ahmed Hamdy | D26: =SUM(D27:D30) -> 4 | E26: =ROUNDUP(D26/8,0) -> 1 | F26: =$C$5+INT((W26-1)/5)*7+MOD(W26-1,5) -> 46301 | G26: =$C$5+INT((X26-1)/5)*7+MOD(X26-1,5) -> 46301 | H26: — | I26: No secrets in code; private access only; traces visible | J26: =IF(K26>=1,"Done",IF(COUNTIF(J27:J30,"Blocked")>0,"Blocked",IF(OR(K26>0,COUNTIF(J27:J30,"In progress")>0),"In progress","Not started"))) -> In progress | K26: =IFERROR(SUMPRODUCT(D27:D30,K27:K30)/D26,0) -> 0 | L26: =IFERROR(SUMPRODUCT(D27:D30,L27:L30)/D26,0) -> 0 | M26: =IF(J26="Done","Done",IF(J26="Blocked","Blocked",IF(AND($C$7>X26,K26<1),"Late",""))) | N26: =IF(COUNTIF(J27:J30,"Blocked")>0,"Blocked subtask — see below","") | P26: =IF(AND(W26<=5,X26>=1),1,"") -> 1 | Q26: =IF(AND(W26<=10,X26>=6),1,"") | R26: =IF(AND(W26<=15,X26>=11),1,"") | S26: =IF(AND(W26<=20,X26>=16),1,"") | T26: =IF(AND(W26<=25,X26>=21),1,"") | U26: =IF(AND(W26<=30,X26>=26),1,"") | W26: =MAX(IFERROR(INDEX($X$14:$X$400,MATCH(AC26,$A$14:$A$400,0)),0),IFERROR(INDEX($X$14:$X$400,MATCH(AD26,$A$14:$A$400,0)),0),IFERROR(INDEX($X$14:$X$400,MATCH(AE26,$A$14:$A$400,0)),0),IFERROR(INDEX($X$14:$X$400,MATCH(AF26,$A$14:$A$400,0)),0),IFERROR(INDEX($X$14:$X$400,MATCH(AG26,$A$14:$A$400,0)),0),IFERROR(INDEX($X$14:$X$400,MATCH(AH26,$A$14:$A$400,0)),0),IFERROR(INDEX($X$14:$X$400,MATCH(AI26,$A$14:$A$400,0)),0),IFERROR(INDEX($X$14:$X$400,MATCH(AB26,$A$14:$A$400,0)),0))+1 -> 3 | X26: =W26+Y26-1 -> 3 | Y26: =E26 -> 1 | Z26: T | AA26: Ahmed Hamdy | AB26: A1
A27: A2.1 | B27: Key Vault; move all secrets | C27: Ahmed Hamdy | D27: 1 | E27: =X27-W27+1 -> 1 | F27: =$C$5+INT((W27-1)/5)*7+MOD(W27-1,5) -> 46301 | G27: =$C$5+INT((X27-1)/5)*7+MOD(X27-1,5) -> 46301 | J27: In progress | K27: 0 | L27: =IFERROR(COUNTIFS(Checklist!$D:$D,"A2.1",Checklist!$I:$I,"Yes")/COUNTIF(Checklist!$D:$D,"A2.1"),0) -> 0 | M27: =IF(AND(J27="Done",K27<1),"Check",IF(AND(J27="In progress",K27=0),"Check",IF(AND(K27>=1,J27<>"Done"),"Check",IF(J27="Done","Done",IF(J27="Blocked","Blocked",IF(AND($C$7>X27,K27<1),"Late","")))))) -> Check | P27: =IF(AND(W27<=5,X27>=1),2,"") -> 2 | Q27: =IF(AND(W27<=10,X27>=6),2,"") | R27: =IF(AND(W27<=15,X27>=11),2,"") | S27: =IF(AND(W27<=20,X27>=16),2,"") | T27: =IF(AND(W27<=25,X27>=21),2,"") | U27: =IF(AND(W27<=30,X27>=26),2,"") | W27: =$W$26+INT(SUM(D$27:D27)/8-D27/8+0.0001) -> 3 | X27: =MAX(W27,$W$26+ROUNDUP(SUM(D$27:D27)/8,0)-1) -> 3 | Y27: =E27 -> 1 | Z27: S | AA27: Ahmed Hamdy
A28: A2.2 | B28: Managed identities + RBAC | C28: Ahmed Hamdy | D28: 1 | E28: =X28-W28+1 -> 1 | F28: =$C$5+INT((W28-1)/5)*7+MOD(W28-1,5) -> 46301 | G28: =$C$5+INT((X28-1)/5)*7+MOD(X28-1,5) -> 46301 | J28: In progress | K28: 0 | L28: =IFERROR(COUNTIFS(Checklist!$D:$D,"A2.2",Checklist!$I:$I,"Yes")/COUNTIF(Checklist!$D:$D,"A2.2"),0) -> 0 | M28: =IF(AND(J28="Done",K28<1),"Check",IF(AND(J28="In progress",K28=0),"Check",IF(AND(K28>=1,J28<>"Done"),"Check",IF(J28="Done","Done",IF(J28="Blocked","Blocked",IF(AND($C$7>X28,K28<1),"Late","")))))) -> Check | P28: =IF(AND(W28<=5,X28>=1),2,"") -> 2 | Q28: =IF(AND(W28<=10,X28>=6),2,"") | R28: =IF(AND(W28<=15,X28>=11),2,"") | S28: =IF(AND(W28<=20,X28>=16),2,"") | T28: =IF(AND(W28<=25,X28>=21),2,"") | U28: =IF(AND(W28<=30,X28>=26),2,"") | W28: =$W$26+INT(SUM(D$27:D28)/8-D28/8+0.0001) -> 3 | X28: =MAX(W28,$W$26+ROUNDUP(SUM(D$27:D28)/8,0)-1) -> 3 | Y28: =E28 -> 1 | Z28: S | AA28: Ahmed Hamdy
A29: A2.3 | B29: Private endpoints + DNS (Foundry, Key Vault) | C29: Ahmed Hamdy | D29: 1 | E29: =X29-W29+1 -> 1 | F29: =$C$5+INT((W29-1)/5)*7+MOD(W29-1,5) -> 46301 | G29: =$C$5+INT((X29-1)/5)*7+MOD(X29-1,5) -> 46301 | J29: In progress | K29: 0 | L29: =IFERROR(COUNTIFS(Checklist!$D:$D,"A2.3",Checklist!$I:$I,"Yes")/COUNTIF(Checklist!$D:$D,"A2.3"),0) -> 0 | M29: =IF(AND(J29="Done",K29<1),"Check",IF(AND(J29="In progress",K29=0),"Check",IF(AND(K29>=1,J29<>"Done"),"Check",IF(J29="Done","Done",IF(J29="Blocked","Blocked",IF(AND($C$7>X29,K29<1),"Late","")))))) -> Check | P29: =IF(AND(W29<=5,X29>=1),2,"") -> 2 | Q29: =IF(AND(W29<=10,X29>=6),2,"") | R29: =IF(AND(W29<=15,X29>=11),2,"") | S29: =IF(AND(W29<=20,X29>=16),2,"") | T29: =IF(AND(W29<=25,X29>=21),2,"") | U29: =IF(AND(W29<=30,X29>=26),2,"") | W29: =$W$26+INT(SUM(D$27:D29)/8-D29/8+0.0001) -> 3 | X29: =MAX(W29,$W$26+ROUNDUP(SUM(D$27:D29)/8,0)-1) -> 3 | Y29: =E29 -> 1 | Z29: S | AA29: Ahmed Hamdy
A30: A2.4 | B30: App Insights, no patient text in logs | C30: Ahmed Hamdy | D30: 1 | E30: =X30-W30+1 -> 1 | F30: =$C$5+INT((W30-1)/5)*7+MOD(W30-1,5) -> 46301 | G30: =$C$5+INT((X30-1)/5)*7+MOD(X30-1,5) -> 46301 | J30: In progress | K30: 0 | L30: =IFERROR(COUNTIFS(Checklist!$D:$D,"A2.4",Checklist!$I:$I,"Yes")/COUNTIF(Checklist!$D:$D,"A2.4"),0) -> 0 | M30: =IF(AND(J30="Done",K30<1),"Check",IF(AND(J30="In progress",K30=0),"Check",IF(AND(K30>=1,J30<>"Done"),"Check",IF(J30="Done","Done",IF(J30="Blocked","Blocked",IF(AND($C$7>X30,K30<1),"Late","")))))) -> Check | P30: =IF(AND(W30<=5,X30>=1),2,"") -> 2 | Q30: =IF(AND(W30<=10,X30>=6),2,"") | R30: =IF(AND(W30<=15,X30>=11),2,"") | S30: =IF(AND(W30<=20,X30>=16),2,"") | T30: =IF(AND(W30<=25,X30>=21),2,"") | U30: =IF(AND(W30<=30,X30>=26),2,"") | W30: =$W$26+INT(SUM(D$27:D30)/8-D30/8+0.0001) -> 3 | X30: =MAX(W30,$W$26+ROUNDUP(SUM(D$27:D30)/8,0)-1) -> 3 | Y30: =E30 -> 1 | Z30: S | AA30: Ahmed Hamdy
A31: B5 | B31: Incremental structuring: structure each transcript segment live, consolidate at end | C31: Ahmed Hamdy | D31: =SUM(D32:D34) -> 8 | E31: =ROUNDUP(D31/8,0) -> 1 | F31: =$C$5+INT((W31-1)/5)*7+MOD(W31-1,5) -> 46302 | G31: =$C$5+INT((X31-1)/5)*7+MOD(X31-1,5) -> 46302 | H31: B1 | I31: Final note ≤ 3 s after stop; no fidelity loss | J31: =IF(K31>=1,"Done",IF(COUNTIF(J32:J34,"Blocked")>0,"Blocked",IF(OR(K31>0,COUNTIF(J32:J34,"In progress")>0),"In progress","Not started"))) -> In progress | K31: =IFERROR(SUMPRODUCT(D32:D34,K32:K34)/D31,0) -> 0 | L31: =IFERROR(SUMPRODUCT(D32:D34,L32:L34)/D31,0) -> 0 | M31: =IF(J31="Done","Done",IF(J31="Blocked","Blocked",IF(AND($C$7>X31,K31<1),"Late",""))) | N31: =IF(COUNTIF(J32:J34,"Blocked")>0,"Blocked subtask — see below","") | P31: =IF(AND(W31<=5,X31>=1),1,"") -> 1 | Q31: =IF(AND(W31<=10,X31>=6),1,"") | R31: =IF(AND(W31<=15,X31>=11),1,"") | S31: =IF(AND(W31<=20,X31>=16),1,"") | T31: =IF(AND(W31<=25,X31>=21),1,"") | U31: =IF(AND(W31<=30,X31>=26),1,"") | W31: =MAX(IFERROR(INDEX($X$14:$X$400,MATCH(AC31,$A$14:$A$400,0)),0),IFERROR(INDEX($X$14:$X$400,MATCH(AD31,$A$14:$A$400,0)),0),IFERROR(INDEX($X$14:$X$400,MATCH(AE31,$A$14:$A$400,0)),0),IFERROR(INDEX($X$14:$X$400,MATCH(AF31,$A$14:$A$400,0)),0),IFERROR(INDEX($X$14:$X$400,MATCH(AG31,$A$14:$A$400,0)),0),IFERROR(INDEX($X$14:$X$400,MATCH(AH31,$A$14:$A$400,0)),0),IFERROR(INDEX($X$14:$X$400,MATCH(AI31,$A$14:$A$400,0)),0),IFERROR(INDEX($X$14:$X$400,MATCH(AB31,$A$14:$A$400,0)),0))+1 -> 4 | X31: =W31+Y31-1 -> 4 | Y31: =E31 -> 1 | Z31: T | AA31: Ahmed Hamdy | AB31: A2 | AC31: B1
A32: B5.1 | B32: Structure each final transcript segment with running context | C32: Ahmed Hamdy | D32: 4 | E32: =X32-W32+1 -> 1 | F32: =$C$5+INT((W32-1)/5)*7+MOD(W32-1,5) -> 46302 | G32: =$C$5+INT((X32-1)/5)*7+MOD(X32-1,5) -> 46302 | J32: In progress | K32: 0 | L32: =IFERROR(COUNTIFS(Checklist!$D:$D,"B5.1",Checklist!$I:$I,"Yes")/COUNTIF(Checklist!$D:$D,"B5.1"),0) -> 0 | M32: =IF(AND(J32="Done",K32<1),"Check",IF(AND(J32="In progress",K32=0),"Check",IF(AND(K32>=1,J32<>"Done"),"Check",IF(J32="Done","Done",IF(J32="Blocked","Blocked",IF(AND($C$7>X32,K32<1),"Late","")))))) -> Check | P32: =IF(AND(W32<=5,X32>=1),2,"") -> 2 | Q32: =IF(AND(W32<=10,X32>=6),2,"") | R32: =IF(AND(W32<=15,X32>=11),2,"") | S32: =IF(AND(W32<=20,X32>=16),2,"") | T32: =IF(AND(W32<=25,X32>=21),2,"") | U32: =IF(AND(W32<=30,X32>=26),2,"") | W32: =$W$31+INT(SUM(D$32:D32)/8-D32/8+0.0001) -> 4 | X32: =MAX(W32,$W$31+ROUNDUP(SUM(D$32:D32)/8,0)-1) -> 4 | Y32: =E32 -> 1 | Z32: S | AA32: Ahmed Hamdy
A33: B5.2 | B33: Consolidation pass when dictation stops | C33: Ahmed Hamdy | D33: 2 | E33: =X33-W33+1 -> 1 | F33: =$C$5+INT((W33-1)/5)*7+MOD(W33-1,5) -> 46302 | G33: =$C$5+INT((X33-1)/5)*7+MOD(X33-1,5) -> 46302 | J33: In progress | K33: 0 | L33: =IFERROR(COUNTIFS(Checklist!$D:$D,"B5.2",Checklist!$I:$I,"Yes")/COUNTIF(Checklist!$D:$D,"B5.2"),0) -> 0 | M33: =IF(AND(J33="Done",K33<1),"Check",IF(AND(J33="In progress",K33=0),"Check",IF(AND(K33>=1,J33<>"Done"),"Check",IF(J33="Done","Done",IF(J33="Blocked","Blocked",IF(AND($C$7>X33,K33<1),"Late","")))))) -> Check | P33: =IF(AND(W33<=5,X33>=1),2,"") -> 2 | Q33: =IF(AND(W33<=10,X33>=6),2,"") | R33: =IF(AND(W33<=15,X33>=11),2,"") | S33: =IF(AND(W33<=20,X33>=16),2,"") | T33: =IF(AND(W33<=25,X33>=21),2,"") | U33: =IF(AND(W33<=30,X33>=26),2,"") | W33: =$W$31+INT(SUM(D$32:D33)/8-D33/8+0.0001) -> 4 | X33: =MAX(W33,$W$31+ROUNDUP(SUM(D$32:D33)/8,0)-1) -> 4 | Y33: =E33 -> 1 | Z33: S | AA33: Ahmed Hamdy
A34: B5.3 | B34: Compare with one-shot on 10 transcripts | C34: Ahmed Hamdy | D34: 2 | E34: =X34-W34+1 -> 1 | F34: =$C$5+INT((W34-1)/5)*7+MOD(W34-1,5) -> 46302 | G34: =$C$5+INT((X34-1)/5)*7+MOD(X34-1,5) -> 46302 | J34: In progress | K34: 0 | L34: =IFERROR(COUNTIFS(Checklist!$D:$D,"B5.3",Checklist!$I:$I,"Yes")/COUNTIF(Checklist!$D:$D,"B5.3"),0) -> 0 | M34: =IF(AND(J34="Done",K34<1),"Check",IF(AND(J34="In progress",K34=0),"Check",IF(AND(K34>=1,J34<>"Done"),"Check",IF(J34="Done","Done",IF(J34="Blocked","Blocked",IF(AND($C$7>X34,K34<1),"Late","")))))) -> Check | P34: =IF(AND(W34<=5,X34>=1),2,"") -> 2 | Q34: =IF(AND(W34<=10,X34>=6),2,"") | R34: =IF(AND(W34<=15,X34>=11),2,"") | S34: =IF(AND(W34<=20,X34>=16),2,"") | T34: =IF(AND(W34<=25,X34>=21),2,"") | U34: =IF(AND(W34<=30,X34>=26),2,"") | W34: =$W$31+INT(SUM(D$32:D34)/8-D34/8+0.0001) -> 4 | X34: =MAX(W34,$W$31+ROUNDUP(SUM(D$32:D34)/8,0)-1) -> 4 | Y34: =E34 -> 1 | Z34: S | AA34: Ahmed Hamdy
A35: B4 | B35: Reasoning router: rule-based triggers, GPT-5.6 Terra default, one-step escalation to Sol, audit | C35: Ahmed Hamdy | D35: =SUM(D36:D38) -> 10 | E35: =ROUNDUP(D35/8,0) -> 2 | F35: =$C$5+INT((W35-1)/5)*7+MOD(W35-1,5) -> 46306 | G35: =$C$5+INT((X35-1)/5)*7+MOD(X35-1,5) -> 46307 | H35: B3, B0 | I35: Every routed case has an audit entry; tests pass | J35: =IF(K35>=1,"Done",IF(COUNTIF(J36:J38,"Blocked")>0,"Blocked",IF(OR(K35>0,COUNTIF(J36:J38,"In progress")>0),"In progress","Not started"))) -> Not started | K35: =IFERROR(SUMPRODUCT(D36:D38,K36:K38)/D35,0) -> 0 | L35: =IFERROR(SUMPRODUCT(D36:D38,L36:L38)/D35,0) -> 0 | M35: =IF(J35="Done","Done",IF(J35="Blocked","Blocked",IF(AND($C$7>X35,K35<1),"Late",""))) | N35: =IF(COUNTIF(J36:J38,"Blocked")>0,"Blocked subtask — see below","") | P35: =IF(AND(W35<=5,X35>=1),1,"") | Q35: =IF(AND(W35<=10,X35>=6),1,"") -> 1 | R35: =IF(AND(W35<=15,X35>=11),1,"") | S35: =IF(AND(W35<=20,X35>=16),1,"") | T35: =IF(AND(W35<=25,X35>=21),1,"") | U35: =IF(AND(W35<=30,X35>=26),1,"") | W35: =MAX(IFERROR(INDEX($X$14:$X$400,MATCH(AC35,$A$14:$A$400,0)),0),IFERROR(INDEX($X$14:$X$400,MATCH(AD35,$A$14:$A$400,0)),0),IFERROR(INDEX($X$14:$X$400,MATCH(AE35,$A$14:$A$400,0)),0),IFERROR(INDEX($X$14:$X$400,MATCH(AF35,$A$14:$A$400,0)),0),IFERROR(INDEX($X$14:$X$400,MATCH(AG35,$A$14:$A$400,0)),0),IFERROR(INDEX($X$14:$X$400,MATCH(AH35,$A$14:$A$400,0)),0),IFERROR(INDEX($X$14:$X$400,MATCH(AI35,$A$14:$A$400,0)),0),IFERROR(INDEX($X$14:$X$400,MATCH(AB35,$A$14:$A$400,0)),0))+1 -> 6 | X35: =W35+Y35-1 -> 7 | Y35: =E35 -> 2 | Z35: T | AA35: Ahmed Hamdy | AB35: B5 | AC35: B3 | AD35: B0
A36: B4.1 | B36: Trigger rules as a pure function | C36: Ahmed Hamdy | D36: 4 | E36: =X36-W36+1 -> 1 | F36: =$C$5+INT((W36-1)/5)*7+MOD(W36-1,5) -> 46306 | G36: =$C$5+INT((X36-1)/5)*7+MOD(X36-1,5) -> 46306 | J36: Not started | K36: 0 | L36: =IFERROR(COUNTIFS(Checklist!$D:$D,"B4.1",Checklist!$I:$I,"Yes")/COUNTIF(Checklist!$D:$D,"B4.1"),0) -> 0 | M36: =IF(AND(J36="Done",K36<1),"Check",IF(AND(J36="In progress",K36=0),"Check",IF(AND(K36>=1,J36<>"Done"),"Check",IF(J36="Done","Done",IF(J36="Blocked","Blocked",IF(AND($C$7>X36,K36<1),"Late","")))))) | P36: =IF(AND(W36<=5,X36>=1),2,"") | Q36: =IF(AND(W36<=10,X36>=6),2,"") -> 2 | R36: =IF(AND(W36<=15,X36>=11),2,"") | S36: =IF(AND(W36<=20,X36>=16),2,"") | T36: =IF(AND(W36<=25,X36>=21),2,"") | U36: =IF(AND(W36<=30,X36>=26),2,"") | W36: =$W$35+INT(SUM(D$36:D36)/8-D36/8+0.0001) -> 6 | X36: =MAX(W36,$W$35+ROUNDUP(SUM(D$36:D36)/8,0)-1) -> 6 | Y36: =E36 -> 1 | Z36: S | AA36: Ahmed Hamdy
A37: B4.2 | B37: Terra default; one escalation to Sol | C37: Ahmed Hamdy | D37: 2 | E37: =X37-W37+1 -> 1 | F37: =$C$5+INT((W37-1)/5)*7+MOD(W37-1,5) -> 46306 | G37: =$C$5+INT((X37-1)/5)*7+MOD(X37-1,5) -> 46306 | J37: Not started | K37: 0 | L37: =IFERROR(COUNTIFS(Checklist!$D:$D,"B4.2",Checklist!$I:$I,"Yes")/COUNTIF(Checklist!$D:$D,"B4.2"),0) -> 0 | M37: =IF(AND(J37="Done",K37<1),"Check",IF(AND(J37="In progress",K37=0),"Check",IF(AND(K37>=1,J37<>"Done"),"Check",IF(J37="Done","Done",IF(J37="Blocked","Blocked",IF(AND($C$7>X37,K37<1),"Late","")))))) | P37: =IF(AND(W37<=5,X37>=1),2,"") | Q37: =IF(AND(W37<=10,X37>=6),2,"") -> 2 | R37: =IF(AND(W37<=15,X37>=11),2,"") | S37: =IF(AND(W37<=20,X37>=16),2,"") | T37: =IF(AND(W37<=25,X37>=21),2,"") | U37: =IF(AND(W37<=30,X37>=26),2,"") | W37: =$W$35+INT(SUM(D$36:D37)/8-D37/8+0.0001) -> 6 | X37: =MAX(W37,$W$35+ROUNDUP(SUM(D$36:D37)/8,0)-1) -> 6 | Y37: =E37 -> 1 | Z37: S | AA37: Ahmed Hamdy
A38: B4.3 | B38: Audit record + unit tests | C38: Ahmed Hamdy | D38: 4 | E38: =X38-W38+1 -> 2 | F38: =$C$5+INT((W38-1)/5)*7+MOD(W38-1,5) -> 46306 | G38: =$C$5+INT((X38-1)/5)*7+MOD(X38-1,5) -> 46307 | J38: Not started | K38: 0 | L38: =IFERROR(COUNTIFS(Checklist!$D:$D,"B4.3",Checklist!$I:$I,"Yes")/COUNTIF(Checklist!$D:$D,"B4.3"),0) -> 0 | M38: =IF(AND(J38="Done",K38<1),"Check",IF(AND(J38="In progress",K38=0),"Check",IF(AND(K38>=1,J38<>"Done"),"Check",IF(J38="Done","Done",IF(J38="Blocked","Blocked",IF(AND($C$7>X38,K38<1),"Late","")))))) | P38: =IF(AND(W38<=5,X38>=1),2,"") | Q38: =IF(AND(W38<=10,X38>=6),2,"") -> 2 | R38: =IF(AND(W38<=15,X38>=11),2,"") | S38: =IF(AND(W38<=20,X38>=16),2,"") | T38: =IF(AND(W38<=25,X38>=21),2,"") | U38: =IF(AND(W38<=30,X38>=26),2,"") | W38: =$W$35+INT(SUM(D$36:D38)/8-D38/8+0.0001) -> 6 | X38: =MAX(W38,$W$35+ROUNDUP(SUM(D$36:D38)/8,0)-1) -> 7 | Y38: =E38 -> 2 | Z38: S | AA38: Ahmed Hamdy
A39: A4 | B39: CI/CD pipeline and staging environment | C39: Ahmed Hamdy | D39: =SUM(D40:D42) -> 11 | E39: =ROUNDUP(D39/8,0) -> 2 | F39: =$C$5+INT((W39-1)/5)*7+MOD(W39-1,5) -> 46308 | G39: =$C$5+INT((X39-1)/5)*7+MOD(X39-1,5) -> 46309 | H39: A2 | I39: Pipeline green; staging reachable privately | J39: =IF(K39>=1,"Done",IF(COUNTIF(J40:J42,"Blocked")>0,"Blocked",IF(OR(K39>0,COUNTIF(J40:J42,"In progress")>0),"In progress","Not started"))) -> Not started | K39: =IFERROR(SUMPRODUCT(D40:D42,K40:K42)/D39,0) -> 0 | L39: =IFERROR(SUMPRODUCT(D40:D42,L40:L42)/D39,0) -> 0 | M39: =IF(J39="Done","Done",IF(J39="Blocked","Blocked",IF(AND($C$7>X39,K39<1),"Late",""))) | N39: =IF(COUNTIF(J40:J42,"Blocked")>0,"Blocked subtask — see below","") | P39: =IF(AND(W39<=5,X39>=1),1,"") | Q39: =IF(AND(W39<=10,X39>=6),1,"") -> 1 | R39: =IF(AND(W39<=15,X39>=11),1,"") | S39: =IF(AND(W39<=20,X39>=16),1,"") | T39: =IF(AND(W39<=25,X39>=21),1,"") | U39: =IF(AND(W39<=30,X39>=26),1,"") | W39: =MAX(IFERROR(INDEX($X$14:$X$400,MATCH(AC39,$A$14:$A$400,0)),0),IFERROR(INDEX($X$14:$X$400,MATCH(AD39,$A$14:$A$400,0)),0),IFERROR(INDEX($X$14:$X$400,MATCH(AE39,$A$14:$A$400,0)),0),IFERROR(INDEX($X$14:$X$400,MATCH(AF39,$A$14:$A$400,0)),0),IFERROR(INDEX($X$14:$X$400,MATCH(AG39,$A$14:$A$400,0)),0),IFERROR(INDEX($X$14:$X$400,MATCH(AH39,$A$14:$A$400,0)),0),IFERROR(INDEX($X$14:$X$400,MATCH(AI39,$A$14:$A$400,0)),0),IFERROR(INDEX($X$14:$X$400,MATCH(AB39,$A$14:$A$400,0)),0))+1 -> 8 | X39: =W39+Y39-1 -> 9 | Y39: =E39 -> 2 | Z39: T | AA39: Ahmed Hamdy | AB39: B4 | AC39: A2
A40: A4.1 | B40: CI pipeline: lint, test, build, push | C40: Ahmed Hamdy | D40: 3 | E40: =X40-W40+1 -> 1 | F40: =$C$5+INT((W40-1)/5)*7+MOD(W40-1,5) -> 46308 | G40: =$C$5+INT((X40-1)/5)*7+MOD(X40-1,5) -> 46308 | J40: Not started | K40: 0 | L40: =IFERROR(COUNTIFS(Checklist!$D:$D,"A4.1",Checklist!$I:$I,"Yes")/COUNTIF(Checklist!$D:$D,"A4.1"),0) -> 0 | M40: =IF(AND(J40="Done",K40<1),"Check",IF(AND(J40="In progress",K40=0),"Check",IF(AND(K40>=1,J40<>"Done"),"Check",IF(J40="Done","Done",IF(J40="Blocked","Blocked",IF(AND($C$7>X40,K40<1),"Late","")))))) | P40: =IF(AND(W40<=5,X40>=1),2,"") | Q40: =IF(AND(W40<=10,X40>=6),2,"") -> 2 | R40: =IF(AND(W40<=15,X40>=11),2,"") | S40: =IF(AND(W40<=20,X40>=16),2,"") | T40: =IF(AND(W40<=25,X40>=21),2,"") | U40: =IF(AND(W40<=30,X40>=26),2,"") | W40: =$W$39+INT(SUM(D$40:D40)/8-D40/8+0.0001) -> 8 | X40: =MAX(W40,$W$39+ROUNDUP(SUM(D$40:D40)/8,0)-1) -> 8 | Y40: =E40 -> 1 | Z40: S | AA40: Ahmed Hamdy
A41: A4.2 | B41: Staging environment | C41: Ahmed Hamdy | D41: 4 | E41: =X41-W41+1 -> 1 | F41: =$C$5+INT((W41-1)/5)*7+MOD(W41-1,5) -> 46308 | G41: =$C$5+INT((X41-1)/5)*7+MOD(X41-1,5) -> 46308 | J41: Not started | K41: 0 | L41: =IFERROR(COUNTIFS(Checklist!$D:$D,"A4.2",Checklist!$I:$I,"Yes")/COUNTIF(Checklist!$D:$D,"A4.2"),0) -> 0 | M41: =IF(AND(J41="Done",K41<1),"Check",IF(AND(J41="In progress",K41=0),"Check",IF(AND(K41>=1,J41<>"Done"),"Check",IF(J41="Done","Done",IF(J41="Blocked","Blocked",IF(AND($C$7>X41,K41<1),"Late","")))))) | P41: =IF(AND(W41<=5,X41>=1),2,"") | Q41: =IF(AND(W41<=10,X41>=6),2,"") -> 2 | R41: =IF(AND(W41<=15,X41>=11),2,"") | S41: =IF(AND(W41<=20,X41>=16),2,"") | T41: =IF(AND(W41<=25,X41>=21),2,"") | U41: =IF(AND(W41<=30,X41>=26),2,"") | W41: =$W$39+INT(SUM(D$40:D41)/8-D41/8+0.0001) -> 8 | X41: =MAX(W41,$W$39+ROUNDUP(SUM(D$40:D41)/8,0)-1) -> 8 | Y41: =E41 -> 1 | Z41: S | AA41: Ahmed Hamdy
A42: A4.3 | B42: Smoke test + approval gate to production | C42: Ahmed Hamdy | D42: 4 | E42: =X42-W42+1 -> 2 | F42: =$C$5+INT((W42-1)/5)*7+MOD(W42-1,5) -> 46308 | G42: =$C$5+INT((X42-1)/5)*7+MOD(X42-1,5) -> 46309 | J42: Not started | K42: 0 | L42: =IFERROR(COUNTIFS(Checklist!$D:$D,"A4.3",Checklist!$I:$I,"Yes")/COUNTIF(Checklist!$D:$D,"A4.3"),0) -> 0 | M42: =IF(AND(J42="Done",K42<1),"Check",IF(AND(J42="In progress",K42=0),"Check",IF(AND(K42>=1,J42<>"Done"),"Check",IF(J42="Done","Done",IF(J42="Blocked","Blocked",IF(AND($C$7>X42,K42<1),"Late","")))))) | P42: =IF(AND(W42<=5,X42>=1),2,"") | Q42: =IF(AND(W42<=10,X42>=6),2,"") -> 2 | R42: =IF(AND(W42<=15,X42>=11),2,"") | S42: =IF(AND(W42<=20,X42>=16),2,"") | T42: =IF(AND(W42<=25,X42>=21),2,"") | U42: =IF(AND(W42<=30,X42>=26),2,"") | W42: =$W$39+INT(SUM(D$40:D42)/8-D42/8+0.0001) -> 8 | X42: =MAX(W42,$W$39+ROUNDUP(SUM(D$40:D42)/8,0)-1) -> 9 | Y42: =E42 -> 2 | Z42: S | AA42: Ahmed Hamdy
...

Sheet Checklist
A1: MedVoice v3.4 — Checklist per subtask
A2: Mark each item Yes only when the evidence exists. The Checklist % on the Tracker updates automatically. Filter by Owner or Task to run your own list.
A5: Items done | C5: =COUNTIF($I$8:$I$400,"Yes")&" of "&COUNTA($G$8:$G$400) -> 0 of 179 | D5: Completion | F5: =IFERROR(COUNTIF($I$8:$I$400,"Yes")/COUNTA($G$8:$G$400),0) -> 0
A7: Owner | B7: Task ID | C7: Task | D7: Subtask ID | E7: Subtask | F7: # | G7: Check item | H7: Evidence to show | I7: Done? | J7: Checked by | K7: Date | L7: Comment
A8: PRE-REQUISITES — outside the AI team
A9: Compliance | B9: X1 | C9: Approve use of de-identified logged sessions as the gold set | D9: X1 | E9: — | F9: 1 | G9: Request submitted with scope, de-identification method and access list | H9: Request reference | I9: No
A10: Compliance | B10: X1 | D10: X1 | F10: 2 | G10: Conditions of use recorded | H10: Approval letter | I10: No
A11: Compliance | B11: X1 | D11: X1 | F11: 3 | G11: Approval shared with AI team | H11: Email / Teams message | I11: No
A12: Coding team | B12: X2 | C12: Export ICD-10 code master from the HIS coding system | D12: X2 | E12: — | F12: 1 | G12: ICD-10 file exported from HIS coding system | H12: codes.csv | I12: No
A13: Coding team | B13: X2 | D13: X2 | F13: 2 | G13: Edition and version stated (e.g. ICD-10-AM) | H13: File header / note | I13: No
A14: Coding team | B14: X2 | D14: X2 | F14: 3 | G14: File received by Mohamed | H14: Message confirming receipt | I14: No
A15: Compliance | B15: X3 | C15: Confirm residency: Foundry region; continued use of Munsit and Voxtral APIs | D15: X3 | E15: — | F15: 1 | G15: Foundry region approved for patient text | H15: Written decision | I15: No
A16: Compliance | B16: X3 | D16: X3 | F16: 2 | G16: Continued use of Munsit and Voxtral APIs approved | H16: Written decision | I16: No
A17: Compliance | B17: X3 | D17: X3 | F17: 3 | G17: Conditions shared with AI team | H17: Email | I17: No
A18: Steering | B18: X4 | C18: Sign acceptance thresholds and pilot site | D18: X4 | E18: — | F18: 1 | G18: Acceptance thresholds reviewed (design 14.3) | H18: Signed sheet | I18: No
A19: Steering | B19: X4 | D19: X4 | F19: 2 | G19: Pilot site and doctors named | H19: List of names | I19: No
A20: Steering | B20: X4 | D20: X4 | F20: 3 | G20: Signed by steering | H20: Signature / minutes | I20: No
A21: AHMED HAMDY — Platform & performance
A22: Ahmed Hamdy | B22: A1 | C22: Fix LLM concurrency: shared async client, 45 s timeout, backoff + jitter, per-model limits, async streaming | D22: A1.1 | E22: Shared async client + 45 s timeout, no hidden retries | F22: 1 | G22: One AsyncOpenAI client created at startup (lifespan) | H22: Code: no client created per request | I22: No
A23: Ahmed Hamdy | B23: A1 | D23: A1.1 | F23: 2 | G23: Timeout 45 s, max_retries=0 set | H23: Config / code | I23: No
A24: Ahmed Hamdy | B24: A1 | D24: A1.1 | F24: 3 | G24: Unit tests pass | H24: CI run | I24: No
A25: Ahmed Hamdy | B25: A1 | D25: A1.2 | E25: Async streaming for refine / translate | F25: 1 | G25: Streaming uses async for on an async stream | H25: Code diff | I25: No
A26: Ahmed Hamdy | B26: A1 | D26: A1.2 | F26: 2 | G26: No blocking loop inside async generator | H26: Code review note | I26: No
A27: Ahmed Hamdy | B27: A1 | D27: A1.3 | E27: Backoff + jitter on 429/5xx; remove key rotation | F27: 1 | G27: Retry only on 429, 5xx, timeouts; honours Retry-After | H27: Code + test | I27: No
A28: Ahmed Hamdy | B28: A1 | D28: A1.3 | F28: 2 | G28: Max 4 attempts with jitter | H28: Config | I28: No
A29: Ahmed Hamdy | B29: A1 | D29: A1.3 | F29: 3 | G29: Key rotation on 429 removed | H29: Code diff | I29: No
A30: Ahmed Hamdy | B30: A1 | D30: A1.4 | E30: Per-model concurrency limits (semaphores) | F30: 1 | G30: Semaphore per model; limit in config | H30: Config file | I30: No
A31: Ahmed Hamdy | B31: A1 | D31: A1.4 | F31: 2 | G31: Limit sized with Little’s law | H31: Calculation note | I31: No
A32: Ahmed Hamdy | B32: A1 | D32: A1.5 | E32: Test: 30 parallel analyses | F32: 1 | G32: 30 parallel analyses complete | H32: Test output | I32: No
A33: Ahmed Hamdy | B33: A1 | D33: A1.5 | F33: 2 | G33: Mocked 429s retried ≤ 3 times each | H33: Test log | I33: No
A34: Ahmed Hamdy | B34: A1 | D34: A1.5 | F34: 3 | G34: Event-loop lag < 50 ms | H34: Measurement | I34: No
A35: Ahmed Hamdy | B35: A2 | C35: Azure foundation: Key Vault, managed identities, private endpoints, App Insights | D35: A2.1 | E35: Key Vault; move all secrets | F35: 1 | G35: Key Vault created; access via RBAC | H35: Azure portal | I35: No
A36: Ahmed Hamdy | B36: A2 | D36: A2.1 | F36: 2 | G36: All secrets moved; none in code or env files | H36: Repo scan | I36: No
A37: Ahmed Hamdy | B37: A2 | D37: A2.2 | E37: Managed identities + RBAC | F37: 1 | G37: User-assigned managed identity created and attached to app | H37: Azure portal | I37: No
A38: Ahmed Hamdy | B38: A2 | D38: A2.2 | F38: 2 | G38: Roles granted (Key Vault Secrets User, Foundry user) | H38: Role assignments | I38: No
A39: Ahmed Hamdy | B39: A2 | D39: A2.3 | E39: Private endpoints + DNS (Foundry, Key Vault) | F39: 1 | G39: Private endpoints for Foundry and Key Vault | H39: Azure portal | I39: No
A40: Ahmed Hamdy | B40: A2 | D40: A2.3 | F40: 2 | G40: Private DNS resolves to private IP from app subnet | H40: nslookup output | I40: No
A41: Ahmed Hamdy | B41: A2 | D41: A2.3 | F41: 3 | G41: Public network access disabled | H41: Resource settings | I41: No
A42: Ahmed Hamdy | B42: A2 | D42: A2.4 | E42: App Insights, no patient text in logs | F42: 1 | G42: App Insights connected (OpenTelemetry) | H42: Traces visible | I42: No
A43: Ahmed Hamdy | B43: A2 | D43: A2.4 | F43: 2 | G43: No transcript or note text in logs | H43: Log sample check | I43: No
...
