Workbook

Sheet Scenarios
A1: Departement | B1: Language | C1: Scenario
A2: ER | B2: EN | C2: 25 years old male presented to ER with a gastric pain and dysnea and shortness of breath. He has a history of diabetes and pre-hypertension. He has no past surgical history. He is a smoker. With no other relevant history. His vitals were okay and his labs showed slightly elevated troponin and his ECG was normal. The patient is for a series of troponin in the CCU and the echocardiogram. If all turned out to be okay, he will be discharged and he will take two days sick leave. His final diagnosis is unstable angina. For follow-up, for admission, sorry.
A3: ER | B3: EN | C3: 60 years old patient, diabetic, hypertensive, and CKD, chronic kidney disease. He presented to ER with DCL and confusion. He has a history of right hip replacement, okay, and appendectomy. On examination, the patient presented drowsy. His acute onset, this was for two days ago. The patient on examination is pale and deliroric, okay, and with disturbed conscious level. His lab showed anemia, hemoglobin 8.5, and TLC elevated, metabolic acidosis, and elevated kidney functions. The patient could be possibly acute kidney injury on top of CKD, or septic shock, or metabolic acidosis. The patient is for ICU and for infectious confology for further workup.
A5: OPD | B5: EN | C5: A 54-year-old male, known case of type 2 diabetes for 8 years and hypertension for 5 years, presents for his first visit with a 3-week history of gradually progressive increased thirst, frequent urination, fatigue, and occasional blurred vision. He denies fever, dysuria, chest pain, shortness of breath, or vomiting. He is currently on metformin 1 gram twice daily, gliclazide 60 mg once daily, and amlodipine 10 mg once daily, with irregular medication adherence and no regular home glucose monitoring. No previous surgical history; no known history of ischemic heart disease, kidney disease, stroke, or diabetic foot problems. He is a non-smoker, does not drink alcohol, follows an irregular high-carbohydrate diet, and has a sedentary lifestyle; his father was diabetic and hypertensive. On examination, he is alert and oriented, BP 148/92 mmHg, pulse 82/min, with no edema or active foot ulcer and otherwise unremarkable cardiovascular, respiratory, and abdominal examination. Plan is to check HbA1c, glucose profile, renal function, urine ACR, lipids, LFTs, and ECG, review medications after results, reinforce medication adherence, diabetic diet, glucose monitoring and foot care, and refer to dietitian and ophthalmology for retinal screening. Follow-up is planned in 2 weeks to review results and treatment response. As this is the first visit, baseline control is documented with no previous treatment outcome available. No known drug allergies.
A6: OPD | B6: EN | C6: A 42-year-old male presents for his first orthopedic visit with gradually progressive right knee pain for 2 months, worsening over the last 3 weeks after increased physical activity. Pain is mainly medial, aggravated by walking, stairs, and squatting, with mild intermittent swelling and stiffness after prolonged sitting. He denies trauma, locking, giving way, fever, or redness. He is known diabetic for 6 years and hypertensive for 3 years, currently taking metformin 1 gram twice daily and amlodipine 5 mg once daily. No previous orthopedic disease or surgery. He is a non-smoker, does not drink alcohol, has a sedentary office job, and reports limited physical activity; his father had knee osteoarthritis. Examination shows mild medial joint-line tenderness and minimal swelling, with painful terminal flexion but no significant restriction or instability; distal neurovascular examination is intact. Plan is weight-bearing bilateral knee X-rays, analgesia as appropriate, activity modification, and home quadriceps-strengthening exercises, with physiotherapy referral. MRI will be considered if clinically indicated. He was advised to avoid prolonged squatting and excessive stairs and to return earlier for significant swelling, fever, or inability to bear weight. Follow-up is planned within 1–2 weeks to review imaging and response to treatment. As this is the first visit, baseline pain and functional status are documented with no previous treatment outcome. No known drug allergies.
A8: Dental | B8: EN | C8: The patient presented today complaining of severe pain in the lower left molar that started approximately one week ago and has progressively worsened over the last three days. The pain is spontaneous and aggravated by hot beverages. The patient has a history of controlled hypertension and is currently taking Amlodipine. Verbal consent was obtained before treatment. A pre-operative periapical radiograph was taken. Clinical and radiographic examination revealed irreversible pulpitis with symptomatic apical periodontitis affecting tooth 36. Root canal treatment was initiated today. Access cavity preparation was completed, working length was determined using apex locator and radiograph, and canal instrumentation was performed up to size 25. Sodium hypochlorite irrigation was used throughout the procedure and calcium hydroxide dressing was placed. Temporary restoration was placed using Cavit. No procedural complications occurred. Oral hygiene instructions and post-operative care instructions were explained to the patient. The treatment plan is currently in progress. The patient is under insurance coverage. An internal referral will be made to Prosthodontics for full coverage crown placement after endodontic treatment completion. The next visit will be for completion of root canal treatment on tooth 36 in one week. Patient retention priority is high.
A9: Dental | B9: EN | C9: Today the patient attended for replacement of a missing upper right first molar. Written consent was obtained. CBCT imaging was reviewed pre-operatively. The missing tooth corresponds to site number 16. The patient denied any significant medical history and is medically fit for surgery. Diagnosis is partially edentulous maxilla due to previous extraction of tooth 16. Implant placement surgery was completed successfully under local anesthesia. A 4.3 by 10 millimeter implant fixture from Straumann was inserted with good primary stability. Xenograft bone substitute was placed around the implant and covered with a collagen membrane. Post-operative CBCT was not required. No complications were encountered during surgery. The patient was educated regarding post-operative instructions, oral hygiene measures, smoking cessation advice and diet recommendations. The treatment plan for implant placement is completed. The case was classified as standard pricing. No internal referrals were required. The patient will return after three months for healing assessment and prosthetic restoration planning. Retention priority is high.

Sheet Extraction
A1: Scenario | B1: Department | C1: Field | D1: Expected | E1: GPT 4o mini | F1: GPT 5.6 Luna | G1: GLM 5.3 Flash | H1: Claude Sonnet 5.5
A2: ER-1 | B2: ER | C2: Airway | D2: Patent | E2: Patent
A3: ER-1 | B3: ER | C3: Breathing | D3: Spontaneous breathing | E3: Spontaneous, shortness of breath noted
A4: ER-1 | B4: ER | C4: Circulation | D4: Hemodynamically stabl | E4: Vitals were okay | F4: Vitals were reported as okay
A5: ER-1 | B5: ER | C5: Disability | D5: No neurological abnormality reported
A6: ER-1 | B6: ER | C6: Exposure | D6: No significant abnormality reported.
A7: ER-1 | B7: ER | C7: Allergy Status | E7: No Known Allergies
A8: ER-1 | B8: ER | C8: Chief Complaint | D8: Epigastric pain associated with dyspnea and shortness of breath. | E8: Gastric pain and dyspnea and shortness of breath | F8: Gastric pain, dyspnea, and shortness of breath | H8: Gastric pain, dyspnea, and shortness of breath
A9: ER-1 | B9: ER | C9: Course | D9: Not specified.
A10: ER-1 | B10: ER | C10: Discharge Instructions | D10: To be determined following completion of cardiac evaluation and if the patient is subsequently deemed suitable for discharge. | E10: If all turned out to be okay, he will be discharged | F10: Conditional discharge if serial troponins and echocardiogram are normal | H10: Not applicable due to admission
A11: ER-1 | B11: ER | C11: Duration | D11: Not specified.
A12: ER-1 | B12: ER | C12: Examination | D12: Vital signs within acceptable range. No other significant examination abnormalities reported. ECG: No acute abnormality detected. Troponin: Mildly elevated. | H12: Vitals reported as okay
A13: ER-1 | B13: ER | C13: Family History
A14: ER-1 | B14: ER | C14: Investigations | E14: Slightly elevated troponin, normal ECG | F14: Slightly elevated troponin; ECG normal | H14: Slightly elevated troponin. ECG normal. Echocardiogram pending.
A15: ER-1 | B15: ER | C15: Medication History | E15: No Medication History
A16: ER-1 | B16: ER | C16: Onset | D16: Not specified.
A17: ER-1 | B17: ER | C17: Past Medical History | D17: Diabetes mellitus. Pre-hypertension. | E17: Diabetes and pre-hypertension | F17: Diabetes and pre-hypertension | H17: Diabetes and pre-hypertension
A18: ER-1 | B18: ER | C18: Past Surgical History | D18: No past surgical history. | E18: No Past Surgical History | F18: No Past Surgical History | H18: No Past Surgical History
A19: ER-1 | B19: ER | C19: Patient Disposition | E19: Admitted to CCU | F19: Planned admission to the CCU for serial troponins and echocardiogram | H19: Admitted to CCU
A20: ER-1 | B20: ER | C20: Plan of Care | D20: Admit to CCU for observation and serial troponin measurements. Echocardiography to be performed. Further management according to serial cardiac biomarkers, echocardiographic findings, and cardiology assessment. | E20: Series of troponin in the CCU and echocardiogram | F20: Admission/monitoring in the CCU with serial troponin testing and echocardiogram; discharge if results are normal | H20: Serial troponin monitoring in the CCU and echocardiogram
A21: ER-1 | B21: ER | C21: Requested Consultation
A22: ER-1 | B22: ER | C22: Sick Leave | D22: 2 days, if discharged after completion of evaluation. | E22: Two days | F22: Two days planned if discharged | H22: Not applicable
A23: ER-1 | B23: ER | C23: Social History | E23: Smoker | F23: Smoker | H23: Smoker
A24: ER-2 | B24: ER | C24: Airway | D24: Patent | E24: Drowsy
A25: ER-2 | B25: ER | C25: Breathing | D25: No acute respiratory abnormality reported | E25: Pale and delirious
A26: ER-2 | B26: ER | C26: Circulation | D26: Requires close hemodynamic monitoring
A27: ER-2 | B27: ER | C27: Disability | D27: Drowsy, delirious, with disturbed conscious level | E27: Disturbed conscious level | F27: Disturbed conscious level; patient drowsy, confused, and delirious | G27: Drowsy, disturbed conscious level | H27: Drowsy, delirious, with disturbed conscious level
A28: ER-2 | B28: ER | C28: Exposure | D28: Pale
A29: ER-2 | B29: ER | C29: Allergy Status | E29: No Known Allergies
A30: ER-2 | B30: ER | C30: Chief Complaint | D30: Decreased conscious level and confusion. | E30: DCL and confusion | F30: Disturbed conscious level, confusion, drowsiness, and delirium | G30: Disturbed conscious level (DCL) and confusion | H30: Decreased level of consciousness (DCL), confusion, drowsiness, delirium
A31: ER-2 | B31: ER | C31: Course | D31: Persistent.
A32: ER-2 | B32: ER | C32: Discharge Instructions | D32: Not applicable due to ICU admission. | E32: Not applicable due to admission | F32: Not applicable due to admission | G32: Not applicable due to admission | H32: Not applicable due to admission
A33: ER-2 | B33: ER | C33: Duration | D33: 2 days. | E33: 2 days | F33: 2 days | G33: 2 days | H33: 2 days
A34: ER-2 | B34: ER | C34: Examination | D34: Patient is drowsy, pale, delirious, and has a disturbed conscious level. Laboratory findings showed anemia with hemoglobin 8.5 g/dL, elevated TLC, metabolic acidosis, and elevated renal function tests. | E34: Pale, drowsy, and delirious | F34: Patient appeared drowsy, pale, and delirious with disturbed conscious level | G34: Drowsy, pale, delirious, with disturbed conscious level | H34: Drowsy, pale, delirious, with disturbed conscious level
A35: ER-2 | B35: ER | C35: Family History
A36: ER-2 | B36: ER | C36: Investigations | E36: Anemia, hemoglobin 8.5, elevated TLC, metabolic acidosis, elevated kidney functions | F36: Hemoglobin 8.5, elevated total leukocyte count, metabolic acidosis, and elevated kidney function tests | G36: Anemia with hemoglobin 8.5, elevated TLC, metabolic acidosis, elevated kidney functions | H36: Anemia with hemoglobin 8.5, elevated TLC, metabolic acidosis, elevated kidney function tests
A37: ER-2 | B37: ER | C37: Medication History
A38: ER-2 | B38: ER | C38: Onset | D38: Acute onset. | E38: Acute onset, 2 days ago | F38: Acute onset, 2 days ago | G38: Acute onset, two days ago | H38: Acute onset, two days ago
A39: ER-2 | B39: ER | C39: Past Medical History | D39: Diabetes mellitus. Hypertension. Chronic kidney disease. | E39: Diabetes, Hypertension, Chronic Kidney Disease | F39: Diabetes mellitus, hypertension, and chronic kidney disease | G39: Diabetes mellitus, hypertension, chronic kidney disease (CKD) | H39: Diabetes mellitus, hypertension, chronic kidney disease
A40: ER-2 | B40: ER | C40: Past Surgical History | D40: Right hip replacement. Appendectomy. | E40: Right hip replacement, appendectomy | F40: Right hip replacement and appendectomy | G40: Right hip replacement, appendectomy | H40: Right hip replacement, appendectomy
...

Sheet Reasoning
A1: Scenario | B1: Department | C1: Field | D1: Expected | E1: GPT 4o mini | F1: Claude Sonnet 5.5 | G1: Claude Opus 5 | H1: Gemini 3.7 Flash
A2: ER-1 | B2: ER | C2: ICD-10 Codes | E2: ["I20.0 - Unstable angina", "R07.9 - Chest pain, unspecified", "R06.02 - Shortness of breath"] | F2: ["I20.0 - Unstable angina", "R79.89 - Other specified abnormal findings of blood chemistry (elevated troponin)", "R07.89 - Other chest pain (epigastric/gastric pain, anginal equivalent)", "R06.02 - Shortness of breath"] | G2: ["I20.0 - Unstable angina", "I21.4 - Non-ST elevation (NSTEMI) myocardial infarction", "R07.9 - Chest pain, unspecified", "R06.02 - Shortness of breath", "F17.210 - Nicotine dependence, cigarettes, uncomplicated"] | H2: ["I20.0 - Unstable angina", "I21.4 - Non-ST elevation (NSTEMI) myocardial infarction", "R10.13 - Epigastric pain", "R06.02 - Shortness of breath"]
A3: ER-1 | B3: ER | C3: Reasoning | E3: The patient's presentation of gastric pain, dyspnea, and elevated troponin levels, along with the final diagnosis of unstable angina, strongly supports the leading diagnosis of I20.0. The normal ECG is reassuring but does not rule out unstable angina, which is a critical condition requiring immediate attention. | F3: The final diagnosis stated by the treating team is unstable angina. A 25-year-old male smoker with diabetes and pre-hypertension has epigastric pain (a possible anginal equivalent) and dyspnea, with a slightly elevated troponin and a normal ECG. This supports a possible acute coronary syndrome that needs serial troponins and an echocardiogram. Because the troponin is elevated, early NSTEMI cannot be excluded, and a minor troponin rise with a normal ECG can also come from myocarditis or pulmonary embolism. Symptom and abnormal-lab codes are listed as fallbacks. | G3: The documented final diagnosis is unstable angina, supported by anginal-equivalent epigastric/gastric pain with dyspnea in a smoker with diabetes and pre-hypertension, a slightly elevated troponin and a non-diagnostic (normal) ECG, with admission for serial troponins and echocardiography. NSTEMI is retained as the closest alternative because a mildly raised troponin could reflect infarction if the serial trend rises, but no ischemic ECG changes or definite rise/fall pattern is yet documented. Symptom codes for chest/epigastric pain and dyspnea plus smoking status are included as supporting/secondary codes; gastric and pulmonary causes remain unexcluded. | H3: The patient presented with anginal equivalents including epigastric/gastric pain and dyspnea alongside cardiac risk factors (diabetes, pre-hypertension, smoking) and an elevated troponin level. The treating clinician documented a final diagnosis of unstable angina requiring admission to the CCU for serial cardiac enzymes and echocardiography. Differential codes reflect acute coronary syndrome spectrum and presenting symptoms.
A4: ER-1 | B4: ER | C4: Differential Diagnoses | D4: Acute coronary syndrome, including unstable angina/NSTEMI. Gastroesophageal or other upper gastrointestinal cause. | E4: Myocardial infarction - Pulmonary embolism - Aortic dissection - Pneumonia - Gastroesophageal reflux disease. | F4: Non-ST-elevation myocardial infarction (NSTEMI) - Pulmonary embolism - Myocarditis or pericarditis - Aortic dissection - Gastritis or peptic ulcer disease - Diabetic ketoacidosis. | G4: Non-ST elevation myocardial infarction - Pulmonary embolism - Gastro-oesophageal reflux / peptic ulcer disease - Myocarditis / pericarditis - Aortic dissection - Anxiety-related chest discomfort. | H4: Non-ST elevation myocardial infarction (NSTEMI) - Acute coronary syndrome - Gastroesophageal reflux disease (GERD) / Gastritis - Acute pancreatitis - Pulmonary embolism - Myocarditis / Pericarditis.
A5: ER-1 | B5: ER | C5: Triage Priority | D5: High-acuity case requiring ICU admission. | E5: ESI 2 - Emergent (stable vitals but concerning symptoms of chest pain and dyspnea with elevated troponin levels) | F5: ESI 2 - Emergent (high-risk presentation with possible ACS, elevated troponin and multiple cardiac risk factors, despite stable vitals and normal ECG) | G5: ESI 2 - Emergent (stable vitals but high-risk ACS presentation with epigastric pain, dyspnea and a positive troponin requiring CCU monitoring) | H5: ESI 2 - Emergent (high-risk presentation of dyspnea, gastric pain, and elevated troponin requiring CCU admission)
A6: ER-2 | B6: ER | C6: ICD-10 Codes | E6: ["N17.9 - Acute kidney failure, unspecified", "R41.81 - Other altered mental status", "D64.9 - Anemia, unspecified", "E11.9 - Type 2 diabetes mellitus without complications", "I10 - Essential (primary) hypertension"] | F6: ["N17.9 - Acute kidney failure, unspecified", "E87.20 - Acidosis, unspecified", "N18.9 - Chronic kidney disease, unspecified", "R41.0 - Disorientation, unspecified", "D64.9 - Anemia, unspecified"] | G6: ["N17.9 - Acute kidney failure, unspecified", "N18.9 - Chronic kidney disease, unspecified", "E87.2 - Acidosis", "A41.9 - Sepsis, unspecified organism", "F05 - Delirium due to known physiological condition"] | H6: ["A41.9 - Sepsis, unspecified organism", "N17.9 - Acute kidney failure, unspecified", "N18.9 - Chronic kidney disease, unspecified", "E87.20 - Acidosis, unspecified", "F05 - Delirium due to known physiological condition"]
A7: ER-2 | B7: ER | C7: Reasoning | E7: The leading diagnosis is acute kidney failure (N17.9) due to the patient's chronic kidney disease (CKD) and the lab findings indicating elevated kidney functions and metabolic acidosis. The acute onset of confusion and drowsiness, along with anemia, supports this diagnosis as the primary concern, especially given the patient's background of CKD. Other diagnoses like altered mental status and anemia are relevant but secondary to the acute kidney failure. | F7: A diabetic, hypertensive patient with known CKD developed acute drowsiness, confusion and delirium over two days, with labs showing elevated kidney function tests and metabolic acidosis. This points most strongly to acute kidney injury on top of CKD with uremic/metabolic encephalopathy, which the treating team also lists first. Elevated TLC and pallor keep sepsis or septic shock a serious concern, but no source, blood pressure or culture result is documented, so N17.9 is leading, with acidosis, CKD, altered mental status and anemia (Hb 8.5) as supporting codes. | G7: The two-day acute onset of confusion and drowsiness in a diabetic, hypertensive patient with known CKD, accompanied by elevated kidney function tests and metabolic acidosis, points to acute kidney injury superimposed on chronic kidney disease as the leading diagnosis, with the resulting uremia/acidosis explaining the delirium. Leukocytosis (elevated TLC) with pallor and anemia (Hb 8.5) raises sepsis as a major co-leading possibility, so A41.9 is retained pending the planned infectious disease workup, but no documented hypotension yet supports coding frank septic shock. Acidosis and delirium are coded as significant concurrent manifestations rather than primary etiologies. | H7: The patient presented with acute onset drowsiness, delirium, elevated total leukocyte count (TLC), severe metabolic acidosis, and acute worsening of renal function requiring ICU admission and an infectious workup, strongly pointing to sepsis/septic shock with multi-organ involvement as the leading cause. Acute kidney injury superimposed on chronic kidney disease and metabolic encephalopathy are major contributing diagnoses addressed in the management plan.
A8: ER-2 | B8: ER | C8: Differential Diagnoses | D8: Acute kidney injury on top of chronic kidney disease. Sepsis / septic shock. Metabolic acidosis with metabolic encephalopathy. | E8: Septic shock - Acute kidney injury - Metabolic acidosis - Hyperglycemic hyperosmolar state - Cerebral hypoxia. | F8: Sepsis / septic shock - Uremic encephalopathy - Diabetic ketoacidosis / hyperosmolar hyperglycemic state - Hypoglycemia - Stroke or intracranial hemorrhage - Anemia of CKD or occult GI bleeding. | G8: Septic shock / urosepsis - Uremic encephalopathy from AKI on CKD - Hypoglycemia or diabetic ketoacidosis / hyperosmolar state - CNS infection (meningitis/encephalitis) - Stroke or intracranial hemorrhage - Drug/toxin-induced delirium. | H8: Sepsis / Septic shock - Uremic encephalopathy secondary to AKI on CKD - Diabetic ketoacidosis or Hyperosmolar hyperglycemic state - Severe systemic infection / Bacteremia - Acute toxic-metabolic encephalopathy.
A9: ER-2 | B9: ER | C9: Triage Priority | D9: High-acuity case requiring ICU admission. | E9: ESI 2 - Emergent (unstable mental status and potential acute kidney injury requiring immediate intervention) | F9: ESI 1 - Resuscitation (altered level of consciousness with metabolic acidosis, possible septic shock, requiring immediate ICU-level intervention) | G9: ESI 2 - Emergent (acute disturbed conscious level with metabolic acidosis, rising creatinine and leukocytosis; high risk for septic shock requiring immediate ICU-level resuscitation) | H9: ESI 2 - Emergent (acute altered mental status, metabolic acidosis, and multi-organ dysfunction requiring ICU admission)
A10: OPD-1 | B10: OPD | C10: ICD-10 Codes | E10: ["E11.65 - Type 2 diabetes mellitus with hyperglycemia", "E11.9 - Type 2 diabetes mellitus without complications", "I10 - Essential (primary) hypertension", "R73.9 - Hyperglycemia, unspecified", "E78.5 - Hyperlipidemia, unspecified"] | F10: ["E11.65 - Type 2 diabetes mellitus with hyperglycemia", "I10 - Essential (primary) hypertension", "Z91.14 - Patient's other noncompliance with medication regimen", "E11.339 - Type 2 diabetes mellitus with moderate nonproliferative diabetic retinopathy without macular edema"] | G10: ["E11.65 - Type 2 diabetes mellitus with hyperglycemia", "I10 - Essential (primary) hypertension", "Z91.14 - Patient's other noncompliance with medication regimen", "E11.9 - Type 2 diabetes mellitus without complications", "Z13.5 - Encounter for screening for eye and ear disorders"] | H10: ["E11.65 - Type 2 diabetes mellitus with hyperglycemia", "I10 - Essential (primary) hypertension", "E11.9 - Type 2 diabetes mellitus without complications"]
A11: OPD-1 | B11: OPD | C11: Reasoning | E11: The leading diagnosis is E11.65 due to the patient's symptoms of increased thirst, frequent urination, fatigue, and occasional blurred vision, which are indicative of hyperglycemia associated with his known type 2 diabetes. The patient's irregular medication adherence and high-carbohydrate diet further support this diagnosis. Hypertension is also present but is secondary to the diabetes-related issues. | F11: Known type 2 diabetes with 3 weeks of polydipsia, polyuria, fatigue and blurred vision, on metformin and gliclazide with irregular adherence and no glucose monitoring, indicates poorly controlled, symptomatic hyperglycemia (E11.65). HbA1c is pending, so hyperglycemia is inferred from symptoms rather than a confirmed value. Hypertension with BP 148/92 on amlodipine is a separate, active comorbidity. Retinopathy is only a possibility for the blurred vision and is not confirmed. Retinal screening is planned, so the retinopathy code is listed last as the least likely and tentative. | G11: The 3-week history of polydipsia, polyuria, fatigue and intermittent blurred vision in a known 8-year type 2 diabetic with irregular adherence and no home monitoring points to symptomatic hyperglycaemia/poor glycaemic control, making E11.65 the leading code over uncomplicated E11.9, which is retained only as a fallback pending HbA1c and glucose profile. Hypertension is separately coded given BP 148/92 mmHg on amlodipine 10 mg daily, indicating inadequate control. Documented irregular medication adherence supports Z91.14, and the referral to ophthalmology for retinal screening with no established retinopathy supports a screening code rather than a complication code. | H11: The patient presents with classic osmotic symptoms of uncontrolled hyperglycemia, including progressive polydipsia, polyuria, fatigue, and blurred vision, driven by poor medication adherence and diet. Essential hypertension is also actively managed given his documented history and elevated clinic blood pressure of 148/92 mmHg.
A12: OPD-2 | B12: OPD | C12: ICD-10 Codes | E12: ["M17.12 - Unilateral primary osteoarthritis of the knee, right knee", "M25.561 - Pain in right knee", "M17.9 - Osteoarthritis of knee, unspecified", "M23.9 - Internal derangement of knee, unspecified", "M79.1 - Myalgia"] | F12: ["M17.11 - Unilateral primary osteoarthritis, right knee", "M25.561 - Pain in right knee", "M23.201 - Derangement of unspecified meniscus due to old tear or injury, right knee", "E11.9 - Type 2 diabetes mellitus without complications", "I10 - Essential (primary) hypertension"] | G12: ["M25.561 - Pain in right knee", "M17.11 - Unilateral primary osteoarthritis, right knee", "M25.461 - Effusion, right knee", "E11.9 - Type 2 diabetes mellitus without complications", "I10 - Essential (primary) hypertension"] | H12: ["M25.561 - Pain in right knee", "M17.11 - Unilateral primary osteoarthritis, right knee", "M23.8X1 - Other internal derangements of right knee", "E11.9 - Type 2 diabetes mellitus without complications", "I10 - Essential (primary) hypertension"]
A13: OPD-2 | B13: OPD | C13: Reasoning | E13: The leading diagnosis of unilateral primary osteoarthritis of the right knee is supported by the patient's symptoms of gradually progressive knee pain, particularly medial pain aggravated by activity, and mild swelling. The absence of trauma and the patient's family history of knee osteoarthritis further reinforce this diagnosis. Other codes, such as pain in the right knee, are relevant but secondary to the primary diagnosis of osteoarthritis. | F13: A 42-year-old with 2 months of gradually progressive medial knee pain, aggravated by walking, stairs and squatting, with stiffness after prolonged sitting, mild intermittent swelling, and a family history of knee osteoarthritis, points to early primary osteoarthritis. Medial joint-line tenderness and painful terminal flexion without locking, instability or trauma make a meniscal lesion less likely, though it remains an alternative until imaging. Osteoarthritis is not yet confirmed by X-ray, so knee pain is the fallback code. Diabetes and hypertension are documented comorbidities. | G13: Today's documentation supports a symptom-level diagnosis as the leading code: 2 months of gradually progressive medial right knee pain with mild medial joint-line tenderness, minimal swelling and painful terminal flexion, but weight-bearing X-rays are still pending, so degenerative change is not yet radiographically confirmed. Early primary osteoarthritis of the right knee is the strongest differential given the activity-related mechanical pain on stairs/squatting, post-sitting stiffness, sedentary habitus, and a father with knee osteoarthritis — it is listed second pending imaging. Intermittent effusion is coded for the minimal swelling, and the actively treated comorbidities (metformin-treated type 2 diabetes for 6 years, amlodipine-treated hypertension for 3 years) are included as they affect management; absence of trauma, locking, or giving way argues against meniscal or ligamentous injury, and absence of fever or redness argues against septic or inflammatory arthritis. | H13: The patient presents with non-traumatic, gradually progressive medial right knee pain aggravated by stairs, squatting, and walking, alongside mild medial joint-line tenderness and painful terminal flexion on physical exam. Symptomatic right knee pain is the leading working diagnosis pending weight-bearing radiographs to evaluate for early osteoarthritis or internal derangement. Managed comorbidities of diabetes and hypertension are documented as co-existing conditions.
A14: DENTAL-1 | B14: DENTAL | C14: ICD-10 Codes | D14: Irreversible pulpitis | E14: ["K04.0 - Pulpitis", "K04.4 - Acute apical periodontitis of pulpal origin", "K04.7 - Other diseases of pulp and periapical tissues"] | F14: ["K04.02 - Irreversible pulpitis", "K04.4 - Acute apical periodontitis of pulpal origin", "I10 - Essential (primary) hypertension (controlled, on Amlodipine)"] | G14: ["K04.02 - Irreversible pulpitis", "K04.4 - Acute apical periodontitis of pulpal origin", "K04.7 - Periapical abscess without sinus", "I10 - Essential (primary) hypertension", "Z01.20 - Encounter for dental examination and cleaning without abnormal findings"] | H14: ["K04.01 - Irreversible pulpitis", "K04.4 - Acute apical periodontitis of pulpal origin"]
A15: DENTAL-1 | B15: DENTAL | C15: Reasoning | E15: The patient presented with severe pain in the lower left molar, which has been progressively worsening, indicating a significant dental issue. The clinical and radiographic examination confirmed irreversible pulpitis with symptomatic apical periodontitis affecting tooth 36, making K04.0 the leading diagnosis. The presence of apical periodontitis further supports the inclusion of K04.4 as a secondary diagnosis. | F15: The clinical and radiographic examination of tooth 36 explicitly found irreversible pulpitis. This fits the severe spontaneous pain that has worsened over three days and is aggravated by hot beverages, and it is the main reason root canal treatment was started. Symptomatic apical periodontitis is also documented and is coded second as a coexisting periapical diagnosis. Controlled hypertension is a relevant comorbidity but is not the reason for the visit. | G15: Today's documentation explicitly describes spontaneous, progressively worsening severe pain in tooth 36 aggravated by heat — the classic hallmark of irreversible pulpitis — and the clinician's own clinical/radiographic diagnosis confirms it, making K04.02 the leading code over reversible pulpitis (which would show only brief stimulus-evoked pain). K04.4 is coded secondarily because symptomatic apical periodontitis was diagnosed, supported by the pre-operative periapical radiograph and the initiation of root canal therapy with working-length determination. K04.7 is listed as a lower-likelihood alternative only because no swelling, sinus tract, or suppuration was documented. I10 is included as a relevant comorbidity given controlled hypertension on Amlodipine, which affects treatment planning rather than the primary dental diagnosis. | H15: The patient presented with spontaneous, severe pain in tooth 36 aggravated by hot beverages, which directly supports the primary diagnosis of irreversible pulpitis. Clinical and radiographic findings confirmed irreversible pulpitis accompanied by symptomatic apical periodontitis, necessitating the initiation of root canal therapy. Both conditions are explicitly documented from today's examination.
A16: DENTAL-2 | B16: DENTAL | C16: ICD-10 Codes | D16: Missing tooth 16 | E16: ["K08.1 - Partial edentulous arch", "K08.3 - Edentulous arch due to trauma", "K08.9 - Unspecified disorders of teeth and supporting structures"] | F16: ["K08.411 - Partial edentulism, class I, maxilla (acquired loss of teeth, partial, due to extraction)", "K08.121 - Complete loss of teeth due to extraction"] | G16: ["K08.429 - Partial loss of teeth due to extraction, unspecified class", "K08.409 - Partial loss of teeth, unspecified cause, unspecified class", "Z96.5 - Presence of dental and subperiosteal implants", "K08.20 - Unspecified atrophy of edentulous alveolar ridge", "Z46.3 - Encounter for fitting and adjustment of dental prosthetic device"] | H16: ["K08.499 - Partial loss of teeth due to other specified cause, unspecified class", "K08.409 - Partial loss of teeth, unspecified cause, unspecified class", "Z96.5 - Presence of tooth and oral implants"]
A17: DENTAL-2 | B17: DENTAL | C17: Reasoning | E17: The leading diagnosis of partial edentulous maxilla is supported by the patient's missing upper right first molar (tooth 16) due to previous extraction. This directly correlates with the ICD-10 code K08.1, which specifically addresses partial edentulous arches. The other codes are less relevant as they pertain to different causes of edentulousness or unspecified disorders. | F17: The text states the diagnosis is a partially edentulous maxilla from previous extraction of tooth 16 (upper right first molar). An implant with xenograft and a collagen membrane was placed to replace it. The code for acquired partial loss of teeth due to extraction best fits this and was chosen as the leading diagnosis. Only one tooth is missing, so complete tooth loss is much less likely and is listed only as a low-probability alternative. No pathology, infection, or complication is described. The Kennedy class is not stated, so the class I code is a best-fit approximation and the class should be confirmed. No history block was provided. | G17: The note explicitly states a partially edentulous maxilla at site 16 resulting from a previous extraction, which maps directly to partial loss of teeth due to extraction (K08.429) rather than a non-specified cause. The surgical placement of a 4.3 x 10 mm Straumann fixture supports coding the presence of a dental implant (Z96.5), and the use of xenograft with a collagen membrane around the fixture suggests deficient/atrophic ridge volume (K08.20), though no ridge measurements were documented. Planned return in three months for prosthetic restoration planning supports Z46.3 as a secondary/future-care code. | H17: The patient presented with a missing upper right first molar (tooth 16) resulting from a previous extraction, which explicitly supports the leading diagnosis of partial loss of teeth due to a specified cause. The encounter involved successful surgical placement of an endosseous implant fixture with bone grafting to restore the edentulous site. Secondary codes reflect general partial edentulism and post-procedural presence of an oral implant.

Sheet Summary
A1: Scenario | B1: Department | C1: Stage | D1: Model | E1: Model Slug | F1: Latency (sec) | G1: Cost (USD)
A2: ER-1 | B2: er | C2: Extraction | D2: GPT 4o mini | E2: openai/gpt-4o-mini | F2: 4.676 | G2: 0.0003606
A3: ER-1 | B3: er | C3: Extraction | D3: GPT 5.6 Luna | E3: openai/gpt-5.6-luna | F3: 5.526 | G3: 0.0010788
A4: ER-1 | B4: er | C4: Extraction | D4: GLM 5.3 Flash | E4: z-ai/glm-5.3-flash | F4: 62.542 | G4: 0.00190757
A5: ER-1 | B5: er | C5: Extraction | D5: Claude Sonnet 5.5 | E5: anthropic/claude-sonnet-5.5 | F5: 4.116 | G5: 0.009256
A6: ER-1 | B6: er | C6: Reasoning | D6: GPT 4o mini | E6: openai/gpt-4o-mini | F6: 4.269 | G6: 0.000279
A7: ER-1 | B7: er | C7: Reasoning | D7: Gemini 3.7 Flash | E7: google/gemini-3.7-flash | F7: 6.46 | G7: 0.00404325
A8: ER-1 | B8: er | C8: Reasoning | D8: Claude Sonnet 5.5 | E8: anthropic/claude-sonnet-5.5 | F8: 5.232 | G8: 0.009146
A9: ER-1 | B9: er | C9: Reasoning | D9: Claude Opus 5 | E9: anthropic/claude-opus-5 | F9: 10.54 | G9: 0.027405
A10: ER-2 | B10: er | C10: Extraction | D10: GPT 4o mini | E10: openai/gpt-4o-mini | F10: 4.083 | G10: 0.0003708
A11: ER-2 | B11: er | C11: Extraction | D11: GPT 5.6 Luna | E11: openai/gpt-5.6-luna | F11: 5.787 | G11: 0.0011284
A12: ER-2 | B12: er | C12: Extraction | D12: GLM 5.3 Flash | E12: z-ai/glm-5.3-flash | F12: 27.269 | G12: 0.0010953
A13: ER-2 | B13: er | C13: Extraction | D13: Claude Sonnet 5.5 | E13: anthropic/claude-sonnet-5.5 | F13: 4.262 | G13: 0.009932
... A49: DENTAL-2 | B49: dental | C49: Reasoning | D49: Claude Opus 5 | E49: anthropic/claude-opus-5 | F49: 12.855 | G49: 0.02926

Sheet Charts
A1: Model Comparison – Charts
A2: Charts read live from the Summary, Extraction and Reasoning tabs. Latency and cost are averages across the 6 scenarios (per call). Output coverage = share of fields with a reference (Expected) value where the model returned a non-empty answer; it measures completeness, not correctness.
A4: Extraction stage
A5: Model | B5: Avg latency (sec) | C5: Avg cost per call (USD) | D5: Output coverage (%)
A6: GPT 4o mini | B6: =AVERAGEIFS(Summary!$F$2:$F$49,Summary!$C$2:$C$49,"Extraction",Summary!$D$2:$D$49,A6) -> 4.101 | C6: =AVERAGEIFS(Summary!$G$2:$G$49,Summary!$C$2:$C$49,"Extraction",Summary!$D$2:$D$49,A6) -> 0.0003794 | D6: =COUNTIFS(Extraction!D2:D123,"<>",Extraction!E2:E123,"<>")/COUNTIF(Extraction!D2:D123,"<>") -> 0.82653061
A7: GPT 5.6 Luna | B7: =AVERAGEIFS(Summary!$F$2:$F$49,Summary!$C$2:$C$49,"Extraction",Summary!$D$2:$D$49,A7) -> 5.5293333 | C7: =AVERAGEIFS(Summary!$G$2:$G$49,Summary!$C$2:$C$49,"Extraction",Summary!$D$2:$D$49,A7) -> 0.0010662667 | D7: =COUNTIFS(Extraction!D2:D123,"<>",Extraction!F2:F123,"<>")/COUNTIF(Extraction!D2:D123,"<>") -> 0.82653061
A8: GLM 5.3 Flash | B8: =AVERAGEIFS(Summary!$F$2:$F$49,Summary!$C$2:$C$49,"Extraction",Summary!$D$2:$D$49,A8) -> 55.088 | C8: =AVERAGEIFS(Summary!$G$2:$G$49,Summary!$C$2:$C$49,"Extraction",Summary!$D$2:$D$49,A8) -> 0.0012307458 | D8: =COUNTIFS(Extraction!D2:D123,"<>",Extraction!G2:G123,"<>")/COUNTIF(Extraction!D2:D123,"<>") -> 0.7244898
A9: Claude Sonnet 5.5 | B9: =AVERAGEIFS(Summary!$F$2:$F$49,Summary!$C$2:$C$49,"Extraction",Summary!$D$2:$D$49,A9) -> 6.6286667 | C9: =AVERAGEIFS(Summary!$G$2:$G$49,Summary!$C$2:$C$49,"Extraction",Summary!$D$2:$D$49,A9) -> 0.012610667 | D9: =COUNTIFS(Extraction!D2:D123,"<>",Extraction!H2:H123,"<>")/COUNTIF(Extraction!D2:D123,"<>") -> 0.81632653
A28: Reasoning stage
A29: Model | B29: Avg latency (sec) | C29: Avg cost per call (USD) | D29: Output coverage (%)
A30: GPT 4o mini | B30: =AVERAGEIFS(Summary!$F$2:$F$49,Summary!$C$2:$C$49,"Reasoning",Summary!$D$2:$D$49,A30) -> 3.7858333 | C30: =AVERAGEIFS(Summary!$G$2:$G$49,Summary!$C$2:$C$49,"Reasoning",Summary!$D$2:$D$49,A30) -> 0.0002545 | D30: =COUNTIFS(Reasoning!D2:D17,"<>",Reasoning!E2:E17,"<>")/COUNTIF(Reasoning!D2:D17,"<>") -> 1
A31: Claude Sonnet 5.5 | B31: =AVERAGEIFS(Summary!$F$2:$F$49,Summary!$C$2:$C$49,"Reasoning",Summary!$D$2:$D$49,A31) -> 4.4796667 | C31: =AVERAGEIFS(Summary!$G$2:$G$49,Summary!$C$2:$C$49,"Reasoning",Summary!$D$2:$D$49,A31) -> 0.0074243333 | D31: =COUNTIFS(Reasoning!D2:D17,"<>",Reasoning!F2:F17,"<>")/COUNTIF(Reasoning!D2:D17,"<>") -> 1
A32: Claude Opus 5 | B32: =AVERAGEIFS(Summary!$F$2:$F$49,Summary!$C$2:$C$49,"Reasoning",Summary!$D$2:$D$49,A32) -> 10.315333 | C32: =AVERAGEIFS(Summary!$G$2:$G$49,Summary!$C$2:$C$49,"Reasoning",Summary!$D$2:$D$49,A32) -> 0.026234167 | D32: =COUNTIFS(Reasoning!D2:D17,"<>",Reasoning!G2:G17,"<>")/COUNTIF(Reasoning!D2:D17,"<>") -> 1
A33: Gemini 3.7 Flash | B33: =AVERAGEIFS(Summary!$F$2:$F$49,Summary!$C$2:$C$49,"Reasoning",Summary!$D$2:$D$49,A33) -> 6.1026667 | C33: =AVERAGEIFS(Summary!$G$2:$G$49,Summary!$C$2:$C$49,"Reasoning",Summary!$D$2:$D$49,A33) -> 0.0035625 | D33: =COUNTIFS(Reasoning!D2:D17,"<>",Reasoning!H2:H17,"<>")/COUNTIF(Reasoning!D2:D17,"<>") -> 1
